Workbook

Sheet Summary
A1: OWASP ASVS 5.0 ? Compliance Tracker (GhostReport Phase 2 Sprint 1)
A5: Chapter | B5: Total Reqs | C5: L1 Total | D5: L1 Compliant | E5: L1 % | F5: L2 Total | G5: L2 Compliant | H5: L2 % | I5: L3 Total | J5: L3 Compliant | K5: L3 % | L5: Overall Compliant | M5: Overall %
A6: V1 – Encoding and Sanitization | B6: 30 | C6: 8 | D6: =COUNTIFS('V1 - Encoding and Sanitization'!$F$2:$F$36,"Compliant",'V1 - Encoding and Sanitization'!$E$2:$E$36,1) -> 3 | E6: =IF(C6=0,"",D6/C6) -> 0.375 | F6: 19 | G6: =COUNTIFS('V1 - Encoding and Sanitization'!$F$2:$F$36,"Compliant",'V1 - Encoding and Sanitization'!$E$2:$E$36,2) -> 1 | H6: =IF(F6=0,"",G6/F6) -> 0.052631579 | I6: 3 | J6: =COUNTIFS('V1 - Encoding and Sanitization'!$F$2:$F$36,"Compliant",'V1 - Encoding and Sanitization'!$E$2:$E$36,3) -> 0 | K6: =IF(I6=0,"",J6/I6) -> 0 | L6: =COUNTIF('V1 - Encoding and Sanitization'!$F$2:$F$36,"Compliant") -> 4 | M6: =IF(B6=0,"",L6/B6) -> 0.13333333
A7: V2 – Validation and Business Logic | B7: 13 | C7: 4 | D7: =COUNTIFS('V2 - Validation and Business Lo'!$F$2:$F$18,"Compliant",'V2 - Validation and Business Lo'!$E$2:$E$18,1) -> 4 | E7: =IF(C7=0,"",D7/C7) -> 1 | F7: 7 | G7: =COUNTIFS('V2 - Validation and Business Lo'!$F$2:$F$18,"Compliant",'V2 - Validation and Business Lo'!$E$2:$E$18,2) -> 0 | H7: =IF(F7=0,"",G7/F7) -> 0 | I7: 2 | J7: =COUNTIFS('V2 - Validation and Business Lo'!$F$2:$F$18,"Compliant",'V2 - Validation and Business Lo'!$E$2:$E$18,3) -> 0 | K7: =IF(I7=0,"",J7/I7) -> 0 | L7: =COUNTIF('V2 - Validation and Business Lo'!$F$2:$F$18,"Compliant") -> 4 | M7: =IF(B7=0,"",L7/B7) -> 0.30769231
A8: V3 – Web Frontend Security | B8: 31 | C8: 8 | D8: =COUNTIFS('V3 - Web Frontend Security'!$F$2:$F$39,"Compliant",'V3 - Web Frontend Security'!$E$2:$E$39,1) -> 3 | E8: =IF(C8=0,"",D8/C8) -> 0.375 | F8: 11 | G8: =COUNTIFS('V3 - Web Frontend Security'!$F$2:$F$39,"Compliant",'V3 - Web Frontend Security'!$E$2:$E$39,2) -> 1 | H8: =IF(F8=0,"",G8/F8) -> 0.090909091 | I8: 12 | J8: =COUNTIFS('V3 - Web Frontend Security'!$F$2:$F$39,"Compliant",'V3 - Web Frontend Security'!$E$2:$E$39,3) -> 0 | K8: =IF(I8=0,"",J8/I8) -> 0 | L8: =COUNTIF('V3 - Web Frontend Security'!$F$2:$F$39,"Compliant") -> 4 | M8: =IF(B8=0,"",L8/B8) -> 0.12903226
A9: V4 – API and Web Service | B9: 16 | C9: 2 | D9: =COUNTIFS('V4 - API and Web Service'!$F$2:$F$21,"Compliant",'V4 - API and Web Service'!$E$2:$E$21,1) -> 1 | E9: =IF(C9=0,"",D9/C9) -> 0.5 | F9: 8 | G9: =COUNTIFS('V4 - API and Web Service'!$F$2:$F$21,"Compliant",'V4 - API and Web Service'!$E$2:$E$21,2) -> 0 | H9: =IF(F9=0,"",G9/F9) -> 0 | I9: 6 | J9: =COUNTIFS('V4 - API and Web Service'!$F$2:$F$21,"Compliant",'V4 - API and Web Service'!$E$2:$E$21,3) -> 1 | K9: =IF(I9=0,"",J9/I9) -> 0.16666667 | L9: =COUNTIF('V4 - API and Web Service'!$F$2:$F$21,"Compliant") -> 2 | M9: =IF(B9=0,"",L9/B9) -> 0.125 | N9: Static Sprint 1 Snapshot | O9: Count
A10: V5 – File Handling | B10: 13 | C10: 4 | D10: =COUNTIFS('V5 - File Handling'!$F$2:$F$18,"Compliant",'V5 - File Handling'!$E$2:$E$18,1) -> 4 | E10: =IF(C10=0,"",D10/C10) -> 1 | F10: 5 | G10: =COUNTIFS('V5 - File Handling'!$F$2:$F$18,"Compliant",'V5 - File Handling'!$E$2:$E$18,2) -> 1 | H10: =IF(F10=0,"",G10/F10) -> 0.2 | I10: 4 | J10: =COUNTIFS('V5 - File Handling'!$F$2:$F$18,"Compliant",'V5 - File Handling'!$E$2:$E$18,3) -> 0 | K10: =IF(I10=0,"",J10/I10) -> 0 | L10: =COUNTIF('V5 - File Handling'!$F$2:$F$18,"Compliant") -> 5 | M10: =IF(B10=0,"",L10/B10) -> 0.38461538 | N10: Compliant | O10: 50
A11: V6 – Authentication | B11: 47 | C11: 13 | D11: =COUNTIFS('V6 - Authentication'!$F$2:$F$56,"Compliant",'V6 - Authentication'!$E$2:$E$56,1) -> 3 | E11: =IF(C11=0,"",D11/C11) -> 0.23076923 | F11: 22 | G11: =COUNTIFS('V6 - Authentication'!$F$2:$F$56,"Compliant",'V6 - Authentication'!$E$2:$E$56,2) -> 0 | H11: =IF(F11=0,"",G11/F11) -> 0 | I11: 12 | J11: =COUNTIFS('V6 - Authentication'!$F$2:$F$56,"Compliant",'V6 - Authentication'!$E$2:$E$56,3) -> 0 | K11: =IF(I11=0,"",J11/I11) -> 0 | L11: =COUNTIF('V6 - Authentication'!$F$2:$F$56,"Compliant") -> 3 | M11: =IF(B11=0,"",L11/B11) -> 0.063829787 | N11: In Progress | O11: 51
A12: V7 – Session Management | B12: 19 | C12: 6 | D12: =COUNTIFS('V7 - Session Management'!$F$2:$F$26,"Compliant",'V7 - Session Management'!$E$2:$E$26,1) -> 3 | E12: =IF(C12=0,"",D12/C12) -> 0.5 | F12: 12 | G12: =COUNTIFS('V7 - Session Management'!$F$2:$F$26,"Compliant",'V7 - Session Management'!$E$2:$E$26,2) -> 2 | H12: =IF(F12=0,"",G12/F12) -> 0.16666667 | I12: 1 | J12: =COUNTIFS('V7 - Session Management'!$F$2:$F$26,"Compliant",'V7 - Session Management'!$E$2:$E$26,3) -> 0 | K12: =IF(I12=0,"",J12/I12) -> 0 | L12: =COUNTIF('V7 - Session Management'!$F$2:$F$26,"Compliant") -> 5 | M12: =IF(B12=0,"",L12/B12) -> 0.26315789 | N12: Not Applicable | O12: 125
A13: V8 – Authorization | B13: 13 | C13: 4 | D13: =COUNTIFS('V8 - Authorization'!$F$2:$F$18,"Compliant",'V8 - Authorization'!$E$2:$E$18,1) -> 4 | E13: =IF(C13=0,"",D13/C13) -> 1 | F13: 3 | G13: =COUNTIFS('V8 - Authorization'!$F$2:$F$18,"Compliant",'V8 - Authorization'!$E$2:$E$18,2) -> 0 | H13: =IF(F13=0,"",G13/F13) -> 0 | I13: 6 | J13: =COUNTIFS('V8 - Authorization'!$F$2:$F$18,"Compliant",'V8 - Authorization'!$E$2:$E$18,3) -> 0 | K13: =IF(I13=0,"",J13/I13) -> 0 | L13: =COUNTIF('V8 - Authorization'!$F$2:$F$18,"Compliant") -> 4 | M13: =IF(B13=0,"",L13/B13) -> 0.30769231 | N13: Not Started | O13: 119
A14: V9 – Self-contained Tokens | B14: 7 | C14: 4 | D14: =COUNTIFS('V9 - Self-contained Tokens'!$F$2:$F$10,"Compliant",'V9 - Self-contained Tokens'!$E$2:$E$10,1) -> 4 | E14: =IF(C14=0,"",D14/C14) -> 1 | F14: 3 | G14: =COUNTIFS('V9 - Self-contained Tokens'!$F$2:$F$10,"Compliant",'V9 - Self-contained Tokens'!$E$2:$E$10,2) -> 0 | H14: =IF(F14=0,"",G14/F14) -> 0 | I14: 0 | J14: N/A | K14: N/A | L14: =COUNTIF('V9 - Self-contained Tokens'!$F$2:$F$10,"Compliant") -> 4 | M14: =IF(B14=0,"",L14/B14) -> 0.57142857 | N14: L1 Compliant | O14: 33 / 70
A15: V10 – OAuth and OIDC | B15: 36 | C15: 5 | D15: =COUNTIFS('V10 - OAuth and OIDC'!$F$2:$F$44,"Compliant",'V10 - OAuth and OIDC'!$E$2:$E$44,1) -> 0 | E15: =IF(C15=0,"",D15/C15) -> 0 | F15: 24 | G15: =COUNTIFS('V10 - OAuth and OIDC'!$F$2:$F$44,"Compliant",'V10 - OAuth and OIDC'!$E$2:$E$44,2) -> 0 | H15: =IF(F15=0,"",G15/F15) -> 0 | I15: 7 | J15: =COUNTIFS('V10 - OAuth and OIDC'!$F$2:$F$44,"Compliant",'V10 - OAuth and OIDC'!$E$2:$E$44,3) -> 0 | K15: =IF(I15=0,"",J15/I15) -> 0 | L15: =COUNTIF('V10 - OAuth and OIDC'!$F$2:$F$44,"Compliant") -> 0 | M15: =IF(B15=0,"",L15/B15) -> 0 | N15: L2 Compliant | O15: 15 / 183
A16: V11 – Cryptography | B16: 24 | C16: 3 | D16: =COUNTIFS('V11 - Cryptography'!$F$2:$F$32,"Compliant",'V11 - Cryptography'!$E$2:$E$32,1) -> 2 | E16: =IF(C16=0,"",D16/C16) -> 0.66666667 | F16: 11 | G16: =COUNTIFS('V11 - Cryptography'!$F$2:$F$32,"Compliant",'V11 - Cryptography'!$E$2:$E$32,2) -> 1 | H16: =IF(F16=0,"",G16/F16) -> 0.090909091 | I16: 10 | J16: =COUNTIFS('V11 - Cryptography'!$F$2:$F$32,"Compliant",'V11 - Cryptography'!$E$2:$E$32,3) -> 0 | K16: =IF(I16=0,"",J16/I16) -> 0 | L16: =COUNTIF('V11 - Cryptography'!$F$2:$F$32,"Compliant") -> 3 | M16: =IF(B16=0,"",L16/B16) -> 0.125 | N16: L3 Compliant | O16: 2 / 92
A17: V12 – Secure Communication | B17: 12 | C17: 3 | D17: =COUNTIFS('V12 - Secure Communication'!$F$2:$F$16,"Compliant",'V12 - Secure Communication'!$E$2:$E$16,1) -> 0 | E17: =IF(C17=0,"",D17/C17) -> 0 | F17: 6 | G17: =COUNTIFS('V12 - Secure Communication'!$F$2:$F$16,"Compliant",'V12 - Secure Communication'!$E$2:$E$16,2) -> 0 | H17: =IF(F17=0,"",G17/F17) -> 0 | I17: 3 | J17: =COUNTIFS('V12 - Secure Communication'!$F$2:$F$16,"Compliant",'V12 - Secure Communication'!$E$2:$E$16,3) -> 0 | K17: =IF(I17=0,"",J17/I17) -> 0 | L17: =COUNTIF('V12 - Secure Communication'!$F$2:$F$16,"Compliant") -> 0 | M17: =IF(B17=0,"",L17/B17) -> 0
A18: V13 – Configuration | B18: 21 | C18: 1 | D18: =COUNTIFS('V13 - Configuration'!$F$2:$F$26,"Compliant",'V13 - Configuration'!$E$2:$E$26,1) -> 0 | E18: =IF(C18=0,"",D18/C18) -> 0 | F18: 12 | G18: =COUNTIFS('V13 - Configuration'!$F$2:$F$26,"Compliant",'V13 - Configuration'!$E$2:$E$26,2) -> 2 | H18: =IF(F18=0,"",G18/F18) -> 0.16666667 | I18: 8 | J18: =COUNTIFS('V13 - Configuration'!$F$2:$F$26,"Compliant",'V13 - Configuration'!$E$2:$E$26,3) -> 0 | K18: =IF(I18=0,"",J18/I18) -> 0 | L18: =COUNTIF('V13 - Configuration'!$F$2:$F$26,"Compliant") -> 2 | M18: =IF(B18=0,"",L18/B18) -> 0.095238095
A19: V14 – Data Protection | B19: 13 | C19: 2 | D19: =COUNTIFS('V14 - Data Protection'!$F$2:$F$17,"Compliant",'V14 - Data Protection'!$E$2:$E$17,1) -> 1 | E19: =IF(C19=0,"",D19/C19) -> 0.5 | F19: 7 | G19: =COUNTIFS('V14 - Data Protection'!$F$2:$F$17,"Compliant",'V14 - Data Protection'!$E$2:$E$17,2) -> 0 | H19: =IF(F19=0,"",G19/F19) -> 0 | I19: 4 | J19: =COUNTIFS('V14 - Data Protection'!$F$2:$F$17,"Compliant",'V14 - Data Protection'!$E$2:$E$17,3) -> 0 | K19: =IF(I19=0,"",J19/I19) -> 0 | L19: =COUNTIF('V14 - Data Protection'!$F$2:$F$17,"Compliant") -> 1 | M19: =IF(B19=0,"",L19/B19) -> 0.076923077
A20: V15 – Secure Coding and Architecture | B20: 21 | C20: 3 | D20: =COUNTIFS('V15 - Secure Coding and Archite'!$F$2:$F$26,"Compliant",'V15 - Secure Coding and Archite'!$E$2:$E$26,1) -> 1 | E20: =IF(C20=0,"",D20/C20) -> 0.33333333 | F20: 10 | G20: =COUNTIFS('V15 - Secure Coding and Archite'!$F$2:$F$26,"Compliant",'V15 - Secure Coding and Archite'!$E$2:$E$26,2) -> 1 | H20: =IF(F20=0,"",G20/F20) -> 0.1 | I20: 8 | J20: =COUNTIFS('V15 - Secure Coding and Archite'!$F$2:$F$26,"Compliant",'V15 - Secure Coding and Archite'!$E$2:$E$26,3) -> 0 | K20: =IF(I20=0,"",J20/I20) -> 0 | L20: =COUNTIF('V15 - Secure Coding and Archite'!$F$2:$F$26,"Compliant") -> 2 | M20: =IF(B20=0,"",L20/B20) -> 0.095238095
A21: V16 – Security Logging and Error Handling | B21: 17 | C21: 0 | D21: N/A | E21: N/A | F21: 16 | G21: =COUNTIFS('V16 - Security Logging and Erro'!$F$2:$F$23,"Compliant",'V16 - Security Logging and Erro'!$E$2:$E$23,2) -> 6 | H21: =IF(F21=0,"",G21/F21) -> 0.375 | I21: 1 | J21: =COUNTIFS('V16 - Security Logging and Erro'!$F$2:$F$23,"Compliant",'V16 - Security Logging and Erro'!$E$2:$E$23,3) -> 1 | K21: =IF(I21=0,"",J21/I21) -> 1 | L21: =COUNTIF('V16 - Security Logging and Erro'!$F$2:$F$23,"Compliant") -> 7 | M21: =IF(B21=0,"",L21/B21) -> 0.41176471
A22: V17 – WebRTC | B22: 12 | C22: 0 | D22: N/A | E22: N/A | F22: 7 | G22: =COUNTIFS('V17 - WebRTC'!$F$2:$F$16,"Compliant",'V17 - WebRTC'!$E$2:$E$16,2) -> 0 | H22: =IF(F22=0,"",G22/F22) -> 0 | I22: 5 | J22: =COUNTIFS('V17 - WebRTC'!$F$2:$F$16,"Compliant",'V17 - WebRTC'!$E$2:$E$16,3) -> 0 | K22: =IF(I22=0,"",J22/I22) -> 0 | L22: =COUNTIF('V17 - WebRTC'!$F$2:$F$16,"Compliant") -> 0 | M22: =IF(B22=0,"",L22/B22) -> 0
A23: TOTAL | B23: =SUM(B6:B22) -> 345 | C23: =SUM(C6:C22) -> 70 | D23: =SUM(D6:D22) -> 33 | E23: =IFERROR(AVERAGE(E6:E22),"") -> 0.49871795 | F23: =SUM(F6:F22) -> 183 | G23: =SUM(G6:G22) -> 15 | H23: =IFERROR(AVERAGE(H6:H22),"") -> 0.073104888 | I23: =SUM(I6:I22) -> 92 | J23: =SUM(J6:J22) -> 2 | K23: =IFERROR(AVERAGE(K6:K22),"") -> 0.072916667 | L23: =SUM(L6:L22) -> 50 | M23: =IFERROR(AVERAGE(M6:M22),"") -> 0.18176152

Sheet Sprint 1 Evidence
A1: Area | B1: ASVS Mapping | C1: Implemented Control | D1: Evidence | E1: Residual Risk / Next Step
A2: Authentication | B2: V6, V7, V9 | C2: JWT Bearer stateless authentication, HS256/HMAC-SHA256 validation, BCrypt password hashing, 3600s configurable expiration. | D2: AuthService.java; JwtService.java; JwtAuthenticationFilter.java; SecurityConfig.java; CreateUserRequest.java | E2: No MFA and no login-specific rate limiting yet.
A3: Authorization | B3: V8 | C3: Central RBAC rules for ADMIN, ANALYST and AUDITOR plus service-level analyst ownership checks. | D3: SecurityConfig.java; ReportService.java; CasePackageService.java; AdminAuthorizationTest; AnalystCaseOwnershipTest; RbacAuthorizationMatrixTest | E3: Full field-level matrix can be expanded.
A4: Input validation | B4: V1, V2 | C4: Jakarta Bean Validation, domain primitives, server-side validation and controlled error handling. | D4: DTO package; SafeFilename.java; TrackingCode.java; ReportDescription.java; GlobalExceptionHandler.java | E4: More negative tests can be added for controllers/errors.
A5: File handling | B5: V5 | C5: 10 MB file limit, MIME/extension allowlist, magic-byte validation, UUID stored names and path normalization. | D5: FileStorageService.java; ReportControllerAttachmentUploadTest; FileStorageServiceTest; SafeFilenameSecurityTest | E5: No real antimalware scanning or global quota.
A6: Tracking code and anonymity | B6: V2, V14, V16 | C6: High-entropy tracking code, hash storage, generic verification behavior, logging minimization. | D6: TrackingCode.java; ReportService.java; TrackingCodeEnumerationTest; AnonymousDataLoggingTest | E6: Advanced abuse detection/CAPTCHA not implemented.
A7: Audit and monitoring | B7: V16 | C7: Audit logs and security alerts for critical operations and suspicious behavior. | D7: AuditLogService.java; SecurityMonitoringService.java; AuditController.java | E7: Logs are not append-only/tamper-proof and not exported to external SIEM.
A8: Evidence and backups | B8: V5, V11, V14, V16 | C8: Evidence packages and backups include manifests and SHA-256 integrity hashes; restore staging avoids direct overwrite. | D8: CasePackageService.java; BackupService.java; BackupServiceIntegrationTest; CasePackageServiceIntegrationTest | E8: No encryption/signature/retention policy yet.
A9: DevSecOps pipeline | B9: V13, V15 | C9: CI tests, JaCoCo, SpotBugs SAST, Dependency-Check SCA, Gitleaks and ZAP baseline DAST with artifacts. | D9: .github/workflows/*.yml; pom.xml; pipeline artifacts | E9: Policy gates and authenticated DAST are future work.

Sheet Assessment Notes
A1: Assessment methodology
A2: Updated for GhostReport Phase 2 Sprint 1 using implemented code, automated tests, GitHub Actions workflows and the Sprint 1 report.
A4: Scope
A5: Spring Boot backend, static HTML/CSS/JavaScript frontend, PostgreSQL persistence, local controlled file storage, backups, JWT backoffice authentication, RBAC, analyst ownership, audit logs, security alerts, SAST/SCA/DAST/secret scanning workflows and automated tests.
A7: Status logic
A8: Compliant = implemented and supported by code/tests/workflows for the current Sprint 1 scope.
A9: In Progress = partially implemented or documented, but with known limitations or future hardening still required.
A10: Not Applicable = outside current GhostReport scope.
A11: Not Started = not implemented or not evidenced in Sprint 1.
A13: Important limitations kept explicit
A14: No real antimalware scanning, no global storage quotas, no MFA, no append-only/tamper-proof audit log store, no distributed rate limiting, no authenticated ZAP scan, no formal SBOM gate.

Sheet V1 - Encoding and Sanitization
A1: Section ID | B1: Section Name | C1: Req ID | D1: Description | E1: Level | F1: Status | G1: Observations | H1: Reference / Link
A2: V1.1 | B2: Encoding and Sanitization Architecture
A3: V1.1 | B3: Encoding and Sanitization Architecture | C3: V1.1.1 | D3: Verify that input is decoded or unescaped into a canonical form only once, it is only decoded when encoded data in that form is expected, and that this is done before processing the input further, for example it is not performed after input validation or sanitization. | E3: 2 | F3: Compliant | G3: Path and filename inputs are canonicalized/normalized before use. FileStorageService resolves paths with toAbsolutePath().normalize() and verifies they remain under the configured base directory. | H3: Sprint 1 report ?6; FileStorageService.java; SafeFilename.java; FileStorageServiceTest; SafeFilenameSecurityTest
A4: V1.1 | B4: Encoding and Sanitization Architecture | C4: V1.1.2 | D4: Verify that the application performs output encoding and escaping either as a final step before being used by the interpreter for which it is intended or by the interpreter itself. | E4: 2 | F4: In Progress | G4: Safe serialization/escaping for responses and downstream interpreters should be confirmed in implementation. | H4: DESOFS Phase 1: input validation in mitigations §13 and tests §14
A5: V1.2 | B5: Injection Prevention
A6: V1.2 | B6: Injection Prevention | C6: V1.2.1 | D6: Verify that output encoding for an HTTP response, HTML document, or XML document is relevant for the context required, such as encoding the relevant characters for HTML elements, HTML attributes, HTML comments, CSS, or HTTP header fields, to avoid changing the message or document structure. | E6: 1 | F6: Not Applicable | G6: Not applicable in the current system design. | H6: N/A – not in current system scope
A7: V1.2 | B7: Injection Prevention | C7: V1.2.2 | D7: Verify that when dynamically building URLs, untrusted data is encoded according to its context (e.g., URL encoding or base64url encoding for query or path parameters). Ensure that only safe URL protocols are permitted (e.g., disallow javascript: or data:). | E7: 1 | F7: Not Applicable | G7: Not applicable in the current system design. | H7: N/A – not in current system scope
A8: V1.2 | B8: Injection Prevention | C8: V1.2.3 | D8: Verify that output encoding or escaping is used when dynamically building JavaScript content (including JSON), to avoid changing the message or document structure (to avoid JavaScript and JSON injection). | E8: 1 | F8: In Progress | G8: Backend JSON responses are generated through Spring/Jackson and validation errors are structured by GlobalExceptionHandler. Further frontend-specific output encoding review remains future hardening. | H8: GlobalExceptionHandler.java; Sprint 1 report ?8
A9: V1.2 | B9: Injection Prevention | C9: V1.2.4 | D9: Verify that data selection or database queries (e.g., SQL, HQL, NoSQL, Cypher) use parameterized queries, ORMs, entity frameworks, or are otherwise protected from SQL Injection and other database injection attacks. This is also relevant when writing stored procedures. | E9: 1 | F9: Compliant | G9: Application data access uses Spring Data JPA repositories and framework-managed query binding. No user-controlled SQL string concatenation is used for business endpoints. | H9: Repository interfaces; service layer; Sprint 1 report ?2
A10: V1.2 | B10: Injection Prevention | C10: V1.2.5 | D10: Verify that the application protects against OS command injection and that operating system calls use parameterized OS queries or use contextual command line output encoding. | E10: 1 | F10: Compliant | G10: No application feature invokes operating system shell commands with user-controlled input. File operations use Java NIO APIs with controlled paths. | H10: FileStorageService.java; BackupService.java
A11: V1.2 | B11: Injection Prevention | C11: V1.2.6 | D11: Verify that the application protects against LDAP injection vulnerabilities, or that specific security controls to prevent LDAP injection have been implemented. | E11: 2 | F11: Not Applicable | G11: Not applicable in the current system design. | H11: N/A – not in current system scope
A12: V1.2 | B12: Injection Prevention | C12: V1.2.7 | D12: Verify that the application is protected against XPath injection attacks by using query parameterization or precompiled queries. | E12: 2 | F12: Not Applicable | G12: Not applicable in the current system design. | H12: N/A – not in current system scope
A13: V1.2 | B13: Injection Prevention | C13: V1.2.8 | D13: Verify that LaTeX processors are configured securely (such as not using the "--shell-escape" flag) and an allowlist of commands is used to prevent LaTeX injection attacks. | E13: 2 | F13: Not Applicable | G13: Not applicable in the current system design. | H13: N/A – not in current system scope
A14: V1.2 | B14: Injection Prevention | C14: V1.2.9 | D14: Verify that the application escapes special characters in regular expressions (typically using a backslash) to prevent them from being misinterpreted as metacharacters. | E14: 2 | F14: In Progress | G14: Regex safety for validation patterns should be reviewed during implementation. | H14: DESOFS Phase 1: input validation in mitigations §13 and tests §14
A15: V1.2 | B15: Injection Prevention | C15: V1.2.10 | D15: Verify that the application is protected against CSV and Formula Injection. The application must follow the escaping rules defined in RFC 4180 sections 2.6 and 2.7 when exporting CSV content. Additionally, when exporting to CSV or other spreadsheet formats (such as XLS, XLSX, or ODF), special characters (including '=', '+', '-', '@', '\t' (tab), and '\0' (null character)) must be escaped with a single quote if they appear as the first character in a field value. | E15: 3 | F15: Not Started | G15: Spreadsheet/CSV export handling is not yet specified; escape dangerous leading characters if exports are added. | H15: Project.pdf: backend API, 3 roles, OS/file ops, ASVS deliverable
A16: V1.3 | B16: Sanitization
A17: V1.3 | B17: Sanitization | C17: V1.3.1 | D17: Verify that all untrusted HTML input from WYSIWYG editors or similar is sanitized using a well-known and secure HTML sanitization library or framework feature. | E17: 1 | F17: Not Applicable | G17: Not applicable in the current system design. | H17: N/A – not in current system scope
A18: V1.3 | B18: Sanitization | C18: V1.3.2 | D18: Verify that the application avoids the use of eval() or other dynamic code execution features such as Spring Expression Language (SpEL). Where there is no alternative, any user input being included must be sanitized before being executed. | E18: 1 | F18: Compliant | G18: No dynamic code execution feature such as eval(), expression evaluation, or user-controlled script execution is used in the backend implementation. | H18: Code review Sprint 1; SpotBugs SAST report
A19: V1.3 | B19: Sanitization | C19: V1.3.3 | D19: Verify that data being passed to a potentially dangerous context is sanitized beforehand to enforce safety measures, such as only allowing characters which are safe for this context and trimming input which is too long. | E19: 2 | F19: In Progress | G19: User input is validated in the design (RS4, RS5), but context-specific sanitization (e.g., for file paths, database queries, or outputs) is not explicitly defined. | H19: DESOFS Phase 1: input validation in mitigations §13 and tests §14
A20: V1.3 | B20: Sanitization | C20: V1.3.4 | D20: Verify that user-supplied Scalable Vector Graphics (SVG) scriptable content is validated or sanitized to contain only tags and attributes (such as draw graphics) that are safe for the application, e.g., do not contain scripts and foreignObject. | E20: 2 | F20: Not Applicable | G20: Not applicable in the current system design. | H20: N/A – not in current system scope
A21: V1.3 | B21: Sanitization | C21: V1.3.5 | D21: Verify that the application sanitizes or disables user-supplied scriptable or expression template language content, such as Markdown, CSS or XSL stylesheets, BBCode, or similar. | E21: 2 | F21: Not Applicable | G21: Not applicable in the current system design. | H21: N/A – not in current system scope
A22: V1.3 | B22: Sanitization | C22: V1.3.6 | D22: Verify that the application protects against Server-side Request Forgery (SSRF) attacks, by validating untrusted data against an allowlist of protocols, domains, paths and ports and sanitizing potentially dangerous characters before using the data to call another service. | E22: 2 | F22: In Progress | G22: The system processes user input but does not define restrictions on external resource access (e.g., URLs, APIs), which may lead to SSRF risks if implemented without proper validation. | H22: DESOFS Phase 1: input validation in mitigations §13 and tests §14
A23: V1.3 | B23: Sanitization | C23: V1.3.7 | D23: Verify that the application protects against template injection attacks by not allowing templates to be built based on untrusted input. Where there is no alternative, any untrusted input being included dynamically during template creation must be sanitized or strictly validated. | E23: 2 | F23: In Progress | G23: No template engine is explicitly defined in the design, but if dynamic content rendering is introduced, input validation and strict separation between templates and user data must be enforced. | H23: DESOFS Phase 1: input validation in mitigations §13 and tests §14
A24: V1.3 | B24: Sanitization | C24: V1.3.8 | D24: Verify that the application appropriately sanitizes untrusted input before use in Java Naming and Directory Interface (JNDI) queries and that JNDI is configured securely to prevent JNDI injection attacks. | E24: 2 | F24: Not Applicable | G24: Not applicable in the current system design. | H24: N/A – not in current system scope
A25: V1.3 | B25: Sanitization | C25: V1.3.9 | D25: Verify that the application sanitizes content before it is sent to memcache to prevent injection attacks. | E25: 2 | F25: Not Applicable | G25: Not applicable in the current system design. | H25: N/A – not in current system scope
A26: V1.3 | B26: Sanitization | C26: V1.3.10 | D26: Verify that format strings which might resolve in an unexpected or malicious way when used are sanitized before being processed. | E26: 2 | F26: In Progress | G26: Input validation is defined, but no explicit handling of format string risks is described in the design. | H26: DESOFS Phase 1: input validation in mitigations §13 and tests §14
A27: V1.3 | B27: Sanitization | C27: V1.3.11 | D27: Verify that the application sanitizes user input before passing to mail systems to protect against SMTP or IMAP injection. | E27: 2 | F27: Not Applicable | G27: Not applicable in the current system design. | H27: N/A – not in current system scope
A28: V1.3 | B28: Sanitization | C28: V1.3.12 | D28: Verify that regular expressions are free from elements causing exponential backtracking, and ensure untrusted input is sanitized to mitigate ReDoS or Runaway Regex attacks. | E28: 3 | F28: In Progress | G28: Input validation is required, but no constraints on regex complexity or protections against ReDoS attacks are defined in the design. | H28: DESOFS Phase 1: input validation in mitigations §13 and tests §14
A29: V1.4 | B29: Memory, String, and Unmanaged Code
A30: V1.4 | B30: Memory, String, and Unmanaged Code | C30: V1.4.1 | D30: Verify that the application uses memory-safe string, safer memory copy and pointer arithmetic to detect or prevent stack, buffer, or heap overflows. | E30: 2 | F30: Not Applicable | G30: Not applicable in the current system design. | H30: N/A – not in current system scope
A31: V1.4 | B31: Memory, String, and Unmanaged Code | C31: V1.4.2 | D31: Verify that sign, range, and input validation techniques are used to prevent integer overflows. | E31: 2 | F31: Not Applicable | G31: Not applicable in the current system design. | H31: N/A – not in current system scope
A32: V1.4 | B32: Memory, String, and Unmanaged Code | C32: V1.4.3 | D32: Verify that dynamically allocated memory and resources are released, and that references or pointers to freed memory are removed or set to null to prevent dangling pointers and use-after-free vulnerabilities. | E32: 2 | F32: Not Applicable | G32: Not applicable in the current system design. | H32: N/A – not in current system scope
A33: V1.5 | B33: Safe Deserialization
A34: V1.5 | B34: Safe Deserialization | C34: V1.5.1 | D34: Verify that the application configures XML parsers to use a restrictive configuration and that unsafe features such as resolving external entities are disabled to prevent XML eXternal Entity (XXE) attacks. | E34: 1 | F34: Not Applicable | G34: The current Sprint 1 implementation does not parse user-supplied XML documents. | H34: Current implementation scope
A35: V1.5 | B35: Safe Deserialization | C35: V1.5.2 | D35: Verify that deserialization of untrusted data enforces safe input handling, such as using an allowlist of object types or restricting client-defined object types, to prevent deserialization attacks. Deserialization mechanisms that are explicitly defined as insecure must not be used with untrusted input. | E35: 2 | F35: Not Started | G35: The design does not specify secure parser configurations or restrictions for deserialization of untrusted data. | H35: DESOFS Phase 1: input validation in mitigations §13 and tests §14
A36: V1.5 | B36: Safe Deserialization | C36: V1.5.3 | D36: Verify that different parsers used in the application for the same data type (e.g., JSON parsers, XML parsers, URL parsers), perform parsing in a consistent way and use the same character encoding mechanism to avoid issues such as JSON Interoperability vulnerabilities or different URI or file parsing behavior being exploited in Remote File Inclusion (RFI) or Server-side Request Forgery (SSRF) attacks. | E36: 3 | F36: Not Started | G36: The design does not specify secure parser configurations or restrictions for deserialization of untrusted data. | H36: DESOFS Phase 1: input validation in mitigations §13 and tests §14

Sheet V2 - Validation and Business Lo
A1: Section ID | B1: Section Name | C1: Req ID | D1: Description | E1: Level | F1: Status | G1: Observations | H1: Reference / Link
A2: V2.1 | B2: Validation and Business Logic Documentation
A3: V2.1 | B3: Validation and Business Logic Documentation | C3: V2.1.1 | D3: Verify that the application's documentation defines input validation rules for how to check the validity of data items against an expected structure. This could be common data formats such as credit card numbers, email addresses, telephone numbers, or it could be an internal data format. | E3: 1 | F3: Compliant | G3: Sprint 1 documents validation rules for DTOs, tracking codes, filenames, MIME types, extensions, file size and business states. | H3: Sprint 1 report ?6, ?7, ?13; DTO classes; FileStorageService.java
A4: V2.1 | B4: Validation and Business Logic Documentation | C4: V2.1.2 | D4: Verify that the application's documentation defines how to validate the logical and contextual consistency of combined data items, such as checking that suburb and ZIP code match. | E4: 2 | F4: In Progress | G4: Contextual rules are implemented for analyst ownership, closed-case handling, evidence packages and backups, but a full business rule catalogue is not yet complete. | H4: ReportService.java; CasePackageService.java; AnalystCaseOwnershipTest; ClosedCaseSecurityTest
A5: V2.1 | B5: Validation and Business Logic Documentation | C5: V2.1.3 | D5: Verify that expectations for business logic limits and validations are documented, including both per-user and globally across the application. | E5: 2 | F5: In Progress | G5: Upload size limits and rate limits are implemented. Global storage quotas and distributed rate limiting remain future work. | H5: RateLimiterService.java; RateLimitProperties.java; FileStorageService.java; Sprint 1 report ?7
A6: V2.2 | B6: Input Validation
A7: V2.2 | B7: Input Validation | C7: V2.2.1 | D7: Verify that input is validated to enforce business or functional expectations for that input. This should either use positive validation against an allow list of values, patterns, and ranges, or be based on comparing the input to an expected structure and logical limits according to predefined rules. For L1, this can focus on input which is used to make specific business or security decisions. For L2 and up, this should apply to all input. | E7: 1 | F7: Compliant | G7: Security-sensitive inputs are validated server-side using Jakarta Bean Validation, domain primitives and service-level checks. | H7: DTO package; TrackingCode.java; SafeFilename.java; ReportDescription.java; FileStorageServiceTest
A8: V2.2 | B8: Input Validation | C8: V2.2.2 | D8: Verify that the application is designed to enforce input validation at a trusted service layer. While client-side validation improves usability and should be encouraged, it must not be relied upon as a security control. | E8: 1 | F8: Compliant | G8: Validation and authorization are enforced in the trusted Spring backend rather than relying on client-side JavaScript. | H8: Controller/service layer; SecurityConfig.java
A9: V2.2 | B9: Input Validation | C9: V2.2.3 | D9: Verify that the application ensures that combinations of related data items are reasonable according to the pre-defined rules. | E9: 2 | F9: In Progress | G9: Cross-field and business-context validation rules are not explicitly defined in the design. | H9: DESOFS Phase 1: input validation in mitigations §11 and tests §12
A10: V2.3 | B10: Business Logic Security
A11: V2.3 | B11: Business Logic Security | C11: V2.3.1 | D11: Verify that the application will only process business logic flows for the same user in the expected sequential step order and without skipping steps. | E11: 1 | F11: Compliant | G11: Main flows enforce expected sequence and state checks, including tracking-code verification, closed-case restrictions and evidence package generation only for closed cases. | H11: PublicReportFlowIntegrationTest; ClosedCaseSecurityTest; CasePackageServiceIntegrationTest
A12: V2.3 | B12: Business Logic Security | C12: V2.3.2 | D12: Verify that business logic limits are implemented per the application's documentation to avoid business logic flaws being exploited. | E12: 2 | F12: In Progress | G12: Documented limits/quotas/rate limiting are part of the threat mitigations. | H12: DESOFS Phase 1: DFD/trust boundaries §9; STRIDE §10; mitigations §11
A13: V2.3 | B13: Business Logic Security | C13: V2.3.3 | D13: Verify that transactions are being used at the business logic level such that either a business logic operation succeeds in its entirety or it is rolled back to the previous correct state. | E13: 2 | F13: Not Started | G13: Transactional rollback behavior for report/file/document creation should be specified during implementation. | H13: DESOFS Phase 1: Project design (no explicit transaction handling defined)
A14: V2.3 | B14: Business Logic Security | C14: V2.3.4 | D14: Verify that business logic level locking mechanisms are used to ensure that limited quantity resources (such as theater seats or delivery slots) cannot be double-booked by manipulating the application's logic. | E14: 2 | F14: Not Applicable | G14: Not applicable in the current system design. | H14: N/A – not in current system scope
A15: V2.3 | B15: Business Logic Security | C15: V2.3.5 | D15: Verify that high-value business logic flows require multi-user approval to prevent unauthorized or accidental actions. This could include but is not limited to large monetary transfers, contract approvals, access to classified information, or safety overrides in manufacturing. | E15: 3 | F15: Not Applicable | G15: Not applicable in the current system design. | H15: N/A – not in current system scope
A16: V2.4 | B16: Anti-automation
A17: V2.4 | B17: Anti-automation | C17: V2.4.1 | D17: Verify that anti-automation controls are in place to protect against excessive calls to application functions that could lead to data exfiltration, garbage-data creation, quota exhaustion, rate-limit breaches, denial-of-service, or overuse of costly resources. | E17: 2 | F17: In Progress | G17: Anti-automation and rate limiting are explicit mitigations for spam, brute force, and DoS. | H17: DESOFS Phase 1: DFD/trust boundaries §9; STRIDE §10; mitigations §11
A18: V2.4 | B18: Anti-automation | C18: V2.4.2 | D18: Verify that business logic flows require realistic human timing, preventing excessively rapid transaction submissions. | E18: 3 | F18: Not Started | G18: Human-timing defenses may help abuse resistance but are not yet specified. | H18: DESOFS Phase 1: DFD/trust boundaries §9; STRIDE §10; mitigations §11

Sheet V3 - Web Frontend Security
A1: Section ID | B1: Section Name | C1: Req ID | D1: Description | E1: Level | F1: Status | G1: Observations | H1: Reference / Link
A2: V3.1 | B2: Web Frontend Security Documentation
A3: V3.1 | B3: Web Frontend Security Documentation | C3: V3.1.1 | D3: Verify that application documentation states the expected security features that browsers using the application must support (such as HTTPS, HTTP Strict Transport Security (HSTS), Content Security Policy (CSP), and other relevant HTTP security mechanisms). It must also define how the application must behave when some of these features are not available (such as warning the user or blocking access). | E3: 3 | F3: Not Started | G3: Backend project may later have a browser client; frontend/browser controls are mostly still to be specified. | H3: Project.pdf: backend API, 3 roles, OS/file ops, ASVS deliverable
A4: V3.2 | B4: Unintended Content Interpretation
A5: V3.2 | B5: Unintended Content Interpretation | C5: V3.2.1 | D5: Verify that security controls are in place to prevent browsers from rendering content or functionality in HTTP responses in an incorrect context (e.g., when an API, a user-uploaded file or other resource is requested directly). Possible controls could include: not serving the content unless HTTP request header fields (such as Sec-Fetch-\*) indicate it is the correct context, using the sandbox directive of the Content-Security-Policy header field or using the attachment disposition type in the Content-Disposition header field. | E5: 1 | F5: In Progress | G5: Security headers are configured and uploaded files are stored outside the static web root. Additional download hardening and browser isolation policies remain future work. | H5: SecurityConfig.java; FileStorageService.java; ZAP report
A6: V3.2 | B6: Unintended Content Interpretation | C6: V3.2.2 | D6: Verify that content intended to be displayed as text, rather than rendered as HTML, is handled using safe rendering functions (such as createTextNode or textContent) to prevent unintended execution of content such as HTML or JavaScript. | E6: 1 | F6: Not Applicable | G6: Not applicable in the current backend-only design; this would only be relevant if a browser-based client were introduced. | H6: N/A – frontend/browser functionality not in current system scope
A7: V3.2 | B7: Unintended Content Interpretation | C7: V3.2.3 | D7: Verify that the application avoids DOM clobbering when using client-side JavaScript by employing explicit variable declarations, performing strict type checking, avoiding storing global variables on the document object, and implementing namespace isolation. | E7: 3 | F7: Not Applicable | G7: Not applicable in the current backend-only design; this would only be relevant if a browser-based client were introduced. | H7: N/A – frontend/browser functionality not in current system scope
A8: V3.3 | B8: Cookie Setup
A9: V3.3 | B9: Cookie Setup | C9: V3.3.1 | D9: Verify that cookies have the 'Secure' attribute set, and if the '\__Host-' prefix is not used for the cookie name, the '__Secure-' prefix must be used for the cookie name. | E9: 1 | F9: Compliant | G9: Secure and HttpOnly cookies are explicitly required for authenticated staff sessions. | H9: DESOFS Phase 1: §5.1 RS1-RS3; AC5/AC8/AC11; STRIDE P5/P6; §12 tests
A10: V3.3 | B10: Cookie Setup | C10: V3.3.2 | D10: Verify that each cookie's 'SameSite' attribute value is set according to the purpose of the cookie, to limit exposure to user interface redress attacks and browser-based request forgery attacks, commonly known as cross-site request forgery (CSRF). | E10: 2 | F10: Not Started | G10: Cookies are in scope for staff sessions, but SameSite/prefix details are not yet specified. | H10: DESOFS Phase 1: §5.1 RS1-RS3; AC5/AC8/AC11; STRIDE P5/P6; §12 tests
A11: V3.3 | B11: Cookie Setup | C11: V3.3.3 | D11: Verify that cookies have the '__Host-' prefix for the cookie name unless they are explicitly designed to be shared with other hosts. | E11: 2 | F11: Not Started | G11: Cookies are in scope for staff sessions, but SameSite/prefix details are not yet specified. | H11: DESOFS Phase 1: §5.1 RS1-RS3; AC5/AC8/AC11; STRIDE P5/P6; §12 tests
A12: V3.3 | B12: Cookie Setup | C12: V3.3.4 | D12: Verify that if the value of a cookie is not meant to be accessible to client-side scripts (such as a session token), the cookie must have the 'HttpOnly' attribute set and the same value (e. g. session token) must only be transferred to the client via the 'Set-Cookie' header field. | E12: 2 | F12: Compliant | G12: Secure and HttpOnly cookies are explicitly required for authenticated staff sessions. | H12: DESOFS Phase 1: §5.1 RS1-RS3; AC5/AC8/AC11; STRIDE P5/P6; §12 tests
A13: V3.3 | B13: Cookie Setup | C13: V3.3.5 | D13: Verify that when the application writes a cookie, the cookie name and value length combined are not over 4096 bytes. Overly large cookies will not be stored by the browser and therefore not sent with requests, preventing the user from using application functionality which relies on that cookie. | E13: 3 | F13: Not Started | G13: Browser cookie behavior is partly covered through secure session requirements; exact header details pending. | H13: DESOFS Phase 1: §5.1 RS1-RS3; AC5/AC8/AC11; STRIDE P5/P6; §12 tests
A14: V3.4 | B14: Browser Security Mechanism Headers
A15: V3.4 | B15: Browser Security Mechanism Headers | C15: V3.4.1 | D15: Verify that a Strict-Transport-Security header field is included on all responses to enforce an HTTP Strict Transport Security (HSTS) policy. A maximum age of at least 1 year must be defined, and for L2 and up, the policy must apply to all subdomains as well. | E15: 1 | F15: Compliant | G15: HSTS is configured in Spring Security with includeSubDomains and max-age. | H15: SecurityConfig.java; SecurityHeadersTest
A16: V3.4 | B16: Browser Security Mechanism Headers | C16: V3.4.2 | D16: Verify that the Cross-Origin Resource Sharing (CORS) Access-Control-Allow-Origin header field is a fixed value by the application, or if the Origin HTTP request header field value is used, it is validated against an allowlist of trusted origins. When 'Access-Control-Allow-Origin: *' needs to be used, verify that the response does not include any sensitive information. | E16: 1 | F16: Not Started | G16: API is browser-consumable; origin allowlist/CORS policy should be documented in implementation. | H16: DESOFS Phase 1: DFD/trust boundaries §9; STRIDE §10; mitigations §13
A17: V3.4 | B17: Browser Security Mechanism Headers | C17: V3.4.3 | D17: Verify that HTTP responses include a Content-Security-Policy response header field which defines directives to ensure the browser only loads and executes trusted content or resources, in order to limit execution of malicious JavaScript. As a minimum, a global policy must be used which includes the directives object-src 'none' and base-uri 'none' and defines either an allowlist or uses nonces or hashes. For an L3 application, a per-response policy with nonces or hashes must be defined. | E17: 2 | F17: Not Started | G17: Not applicable in the current backend-only design; would be relevant if a browser-based client is introduced. | H17: DESOFS Phase 1: DFD/trust boundaries §9; STRIDE §10; mitigations §13
A18: V3.4 | B18: Browser Security Mechanism Headers | C18: V3.4.4 | D18: Verify that all HTTP responses contain an 'X-Content-Type-Options: nosniff' header field. This instructs browsers not to use content sniffing and MIME type guessing for the given response, and to require the response's Content-Type header field value to match the destination resource. For example, the response to a request for a style is only accepted if the response's Content-Type is 'text/css'. This also enables the use of the Cross-Origin Read Blocking (CORB) functionality by the browser. | E18: 2 | F18: Not Started | G18: Not applicable in the current backend-only design; would be relevant if a browser-based client is introduced. | H18: DESOFS Phase 1: DFD/trust boundaries §9; STRIDE §10; mitigations §13
A19: V3.4 | B19: Browser Security Mechanism Headers | C19: V3.4.5 | D19: Verify that the application sets a referrer policy to prevent leakage of technically sensitive data to third-party services via the 'Referer' HTTP request header field. This can be done using the Referrer-Policy HTTP response header field or via HTML element attributes. Sensitive data could include path and query data in the URL, and for internal non-public applications also the hostname. | E19: 2 | F19: Not Started | G19: Not applicable in the current backend-only design; would be relevant if a browser-based client is introduced. | H19: DESOFS Phase 1: DFD/trust boundaries §9; STRIDE §10; mitigations §13
A20: V3.4 | B20: Browser Security Mechanism Headers | C20: V3.4.6 | D20: Verify that the web application uses the frame-ancestors directive of the Content-Security-Policy header field for every HTTP response to ensure that it cannot be embedded by default and that embedding of specific resources is allowed only when necessary. Note that the X-Frame-Options header field, although supported by browsers, is obsolete and may not be relied upon. | E20: 2 | F20: Not Started | G20: Not applicable in the current backend-only design; would be relevant if a browser-based client is introduced. | H20: DESOFS Phase 1: DFD/trust boundaries §9; STRIDE §10; mitigations §13
A21: V3.4 | B21: Browser Security Mechanism Headers | C21: V3.4.7 | D21: Verify that the Content-Security-Policy header field specifies a location to report violations. | E21: 3 | F21: Not Started | G21: Not applicable in the current backend-only design; would be relevant if a browser-based client is introduced. | H21: DESOFS Phase 1: DFD/trust boundaries §9; STRIDE §10; mitigations §13
A22: V3.4 | B22: Browser Security Mechanism Headers | C22: V3.4.8 | D22: Verify that all HTTP responses that initiate a document rendering (such as responses with Content-Type text/html), include the Cross‑Origin‑Opener‑Policy header field with the same-origin directive or the same-origin-allow-popups directive as required. This prevents attacks that abuse shared access to Window objects, such as tabnabbing and frame counting. | E22: 3 | F22: Not Started | G22: Not applicable in the current backend-only design; would be relevant if a browser-based client is introduced. | H22: DESOFS Phase 1: DFD/trust boundaries §9; STRIDE §10; mitigations §13
A23: V3.5 | B23: Browser Origin Separation
A24: V3.5 | B24: Browser Origin Separation | C24: V3.5.1 | D24: Verify that, if the application does not rely on the CORS preflight mechanism to prevent disallowed cross-origin requests to use sensitive functionality, these requests are validated to ensure they originate from the application itself. This may be done by using and validating anti-forgery tokens or requiring extra HTTP header fields that are not CORS-safelisted request-header fields. This is to defend against browser-based request forgery attacks, commonly known as cross-site request forgery (CSRF). | E24: 1 | F24: Not Started | G24: No explicit CSRF or origin validation mechanism is defined in the backend design. | H24: DESOFS Phase 1: DFD/trust boundaries §9; STRIDE §10; mitigations §13
A25: V3.5 | B25: Browser Origin Separation | C25: V3.5.2 | D25: Verify that, if the application relies on the CORS preflight mechanism to prevent disallowed cross-origin use of sensitive functionality, it is not possible to call the functionality with a request which does not trigger a CORS-preflight request. This may require checking the values of the 'Origin' and 'Content-Type' request header fields or using an extra header field that is not a CORS-safelisted header-field. | E25: 1 | F25: Not Started | G25: CORS policy and origin validation are not explicitly defined in the design. | H25: DESOFS Phase 1: DFD/trust boundaries §9; STRIDE §10; mitigations §13
A26: V3.5 | B26: Browser Origin Separation | C26: V3.5.3 | D26: Verify that HTTP requests to sensitive functionality use appropriate HTTP methods such as POST, PUT, PATCH, or DELETE, and not methods defined by the HTTP specification as "safe" such as HEAD, OPTIONS, or GET. Alternatively, strict validation of the Sec-Fetch-* request header fields can be used to ensure that the request did not originate from an inappropriate cross-origin call, a navigation request, or a resource load (such as an image source) where this is not expected. | E26: 1 | F26: Compliant | G26: Sensitive operations use explicit Spring MVC HTTP method mappings and unsupported methods are handled consistently. | H26: Controller classes; GlobalExceptionHandler.java
A27: V3.5 | B27: Browser Origin Separation | C27: V3.5.4 | D27: Verify that separate applications are hosted on different hostnames to leverage the restrictions provided by same-origin policy, including how documents or scripts loaded by one origin can interact with resources from another origin and hostname-based restrictions on cookies. | E27: 2 | F27: Not Started | G27: Application deployment across different origins/hostnames is not defined in the design. | H27: DESOFS Phase 1: §5.1 RS1-RS3; AC5/AC8/AC11; STRIDE P5/P6; §12 tests
A28: V3.5 | B28: Browser Origin Separation | C28: V3.5.5 | D28: Verify that messages received by the postMessage interface are discarded if the origin of the message is not trusted, or if the syntax of the message is invalid. | E28: 2 | F28: Not Applicable | G28: Not applicable in the current backend-only design; this would only be relevant if a browser-based client were introduced. | H28: N/A – frontend/browser functionality not in current system scope
A29: V3.5 | B29: Browser Origin Separation | C29: V3.5.6 | D29: Verify that JSONP functionality is not enabled anywhere across the application to avoid Cross-Site Script Inclusion (XSSI) attacks. | E29: 3 | F29: Not Started | G29: No JSONP usage or related protections are defined in the backend design. | H29: DESOFS Phase 1: DFD/trust boundaries §9; STRIDE §10; mitigations §13
A30: V3.5 | B30: Browser Origin Separation | C30: V3.5.7 | D30: Verify that data requiring authorization is not included in script resource responses, like JavaScript files, to prevent Cross-Site Script Inclusion (XSSI) attacks. | E30: 3 | F30: Not Applicable | G30: Not applicable in the current backend-only design; this would only be relevant if a browser-based client were introduced. | H30: N/A – frontend/browser functionality not in current system scope
A31: V3.5 | B31: Browser Origin Separation | C31: V3.5.8 | D31: Verify that authenticated resources (such as images, videos, scripts, and other documents) can be loaded or embedded on behalf of the user only when intended. This can be accomplished by strict validation of the Sec-Fetch-* HTTP request header fields to ensure that the request did not originate from an inappropriate cross-origin call, or by setting a restrictive Cross-Origin-Resource-Policy HTTP response header field to instruct the browser to block returned content. | E31: 3 | F31: Not Started | G31: No controls for restricting cross-origin resource loading are defined in the design. | H31: DESOFS Phase 1: DFD/trust boundaries §9; STRIDE §10; mitigations §13
A32: V3.6 | B32: External Resource Integrity
A33: V3.6 | B33: External Resource Integrity | C33: V3.6.1 | D33: Verify that client-side assets, such as JavaScript libraries, CSS, or web fonts, are only hosted externally (e.g., on a Content Delivery Network) if the resource is static and versioned and Subresource Integrity (SRI) is used to validate the integrity of the asset. If this is not possible, there should be a documented security decision to justify this for each resource. | E33: 3 | F33: Not Applicable | G33: backend-only API; browser/UI feature not in scope | H33: Project.pdf: backend API, 3 roles, OS/file ops, ASVS deliverable
A34: V3.7 | B34: Other Browser Security Considerations
A35: V3.7 | B35: Other Browser Security Considerations | C35: V3.7.1 | D35: Verify that the application only uses client-side technologies which are still supported and considered secure. Examples of technologies which do not meet this requirement include NSAPI plugins, Flash, Shockwave, ActiveX, Silverlight, NACL, or client-side Java applets. | E35: 2 | F35: Not Applicable | G35: Not applicable in the current backend-only design; this would only be relevant if a browser-based client were introduced. | H35: N/A – frontend/browser functionality not in current system scope
A36: V3.7 | B36: Other Browser Security Considerations | C36: V3.7.2 | D36: Verify that the application will only automatically redirect the user to a different hostname or domain (which is not controlled by the application) where the destination appears on an allowlist. | E36: 2 | F36: Not Applicable | G36: Not applicable in the current backend-only design; this would only be relevant if a browser-based client were introduced. | H36: N/A – frontend/browser functionality not in current system scope
A37: V3.7 | B37: Other Browser Security Considerations | C37: V3.7.3 | D37: Verify that the application shows a notification when the user is being redirected to a URL outside of the application's control, with an option to cancel the navigation. | E37: 3 | F37: Not Started | G37: Backend project may later have a browser client; frontend/browser controls are mostly still to be specified. | H37: Project.pdf: backend API, 3 roles, OS/file ops, ASVS deliverable
A38: V3.7 | B38: Other Browser Security Considerations | C38: V3.7.4 | D38: Verify that the application's top-level domain (e.g., site.tld) is added to the public preload list for HTTP Strict Transport Security (HSTS). This ensures that the use of TLS for the application is built directly into the main browsers, rather than relying only on the Strict-Transport-Security response header field. | E38: 3 | F38: Not Started | G38: HTTPS is required, but HSTS preload configuration is not defined. | H38: DESOFS Phase 1: assumptions §2.2 HTTPS; §5.3 RS7; AC9/AC10
A39: V3.7 | B39: Other Browser Security Considerations | C39: V3.7.5 | D39: Verify that the application behaves as documented (such as warning the user or blocking access) if the browser used to access the application does not support the expected security features. | E39: 3 | F39: Not Started | G39: No browser-specific behavior or fallback mechanisms are defined in the design. | H39: Project.pdf: backend API, 3 roles, OS/file ops, ASVS deliverable

Sheet V4 - API and Web Service
A1: Section ID | B1: Section Name | C1: Req ID | D1: Description | E1: Level | F1: Status | G1: Observations | H1: Reference / Link
A2: V4.1 | B2: Generic Web Service Security
A3: V4.1 | B3: Generic Web Service Security | C3: V4.1.1 | D3: Verify that every HTTP response with a message body contains a Content-Type header field that matches the actual content of the response, including the charset parameter to specify safe character encoding (e.g., UTF-8, ISO-8859-1) according to IANA Media Types, such as "text/", "/+xml" and "/xml". | E3: 1 | F3: Compliant | G3: API responses are produced by Spring MVC and error responses are centralized as JSON through GlobalExceptionHandler. | H3: GlobalExceptionHandler.java; controller package
A4: V4.1 | B4: Generic Web Service Security | C4: V4.1.2 | D4: Verify that only user-facing endpoints (intended for manual web-browser access) automatically redirect from HTTP to HTTPS, while other services or endpoints do not implement transparent redirects. This is to avoid a situation where a client is erroneously sending unencrypted HTTP requests, but since the requests are being automatically redirected to HTTPS, the leakage of sensitive data goes undiscovered. | E4: 2 | F4: Not Started | G4: HTTPS is required, but redirect behavior between HTTP and HTTPS is not defined. | H4: DESOFS Phase 1: assumptions §2.2 HTTPS; §5.3 RS7; AC9/AC10
A5: V4.1 | B5: Generic Web Service Security | C5: V4.1.3 | D5: Verify that any HTTP header field used by the application and set by an intermediary layer, such as a load balancer, a web proxy, or a backend-for-frontend service, cannot be overridden by the end-user. Example headers might include X-Real-IP, X-Forwarded-*, or X-User-ID. | E5: 2 | F5: Not Started | G5: Proxy/load balancer header trust policy is not yet documented. | H5: DESOFS Phase 1: DFD/trust boundaries §9; STRIDE §10; mitigations §11
A6: V4.1 | B6: Generic Web Service Security | C6: V4.1.4 | D6: Verify that only HTTP methods that are explicitly supported by the application or its API (including OPTIONS during preflight requests) can be used and that unused methods are blocked. | E6: 3 | F6: Compliant | G6: Only explicitly mapped HTTP methods are supported by each controller endpoint; unsupported methods are rejected by Spring MVC. | H6: Controller classes; GlobalExceptionHandler.java
A7: V4.1 | B7: Generic Web Service Security | C7: V4.1.5 | D7: Verify that per-message digital signatures are used to provide additional assurance on top of transport protections for requests or transactions which are highly sensitive or which traverse a number of systems. | E7: 3 | F7: Not Applicable | G7: Not applicable in the current system design. | H7: N/A – not in current system scope
A8: V4.2 | B8: HTTP Message Structure Validation
A9: V4.2 | B9: HTTP Message Structure Validation | C9: V4.2.1 | D9: Verify that all application components (including load balancers, firewalls, and application servers) determine boundaries of incoming HTTP messages using the appropriate mechanism for the HTTP version to prevent HTTP request smuggling. In HTTP/1.x, if a Transfer-Encoding header field is present, the Content-Length header must be ignored per RFC 2616. When using HTTP/2 or HTTP/3, if a Content-Length header field is present, the receiver must ensure that it is consistent with the length of the DATA frames. | E9: 2 | F9: Not Started | G9: HTTP message parsing, header validation, and request handling controls are not explicitly defined in the system design. | H9: DESOFS Phase 1: DFD/trust boundaries §9; STRIDE §10; mitigations §11
A10: V4.2 | B10: HTTP Message Structure Validation | C10: V4.2.2 | D10: Verify that when generating HTTP messages, the Content-Length header field does not conflict with the length of the content as determined by the framing of the HTTP protocol, in order to prevent request smuggling attacks. | E10: 3 | F10: Not Started | G10: HTTP message parsing, header validation, and request handling controls are not explicitly defined in the system design. | H10: DESOFS Phase 1: DFD/trust boundaries §9; STRIDE §10; mitigations §11
A11: V4.2 | B11: HTTP Message Structure Validation | C11: V4.2.3 | D11: Verify that the application does not send nor accept HTTP/2 or HTTP/3 messages with connection-specific header fields such as Transfer-Encoding to prevent response splitting and header injection attacks. | E11: 3 | F11: Not Started | G11: HTTP message parsing, header validation, and request handling controls are not explicitly defined in the system design. | H11: DESOFS Phase 1: DFD/trust boundaries §9; STRIDE §10; mitigations §11
A12: V4.2 | B12: HTTP Message Structure Validation | C12: V4.2.4 | D12: Verify that the application only accepts HTTP/2 and HTTP/3 requests where the header fields and values do not contain any CR (\r), LF (\n), or CRLF (\r\n) sequences, to prevent header injection attacks. | E12: 3 | F12: Not Started | G12: HTTP message parsing, header validation, and request handling controls are not explicitly defined in the system design. | H12: DESOFS Phase 1: DFD/trust boundaries §9; STRIDE §10; mitigations §11
