Workbook

Sheet Summary
A1: OWASP ASVS 5.0 – Compliance Tracker
A5: Chapter | B5: Total Reqs | C5: L1 Total | D5: L1 Compliant | E5: L1 % | F5: L2 Total | G5: L2 Compliant | H5: L2 % | I5: L3 Total | J5: L3 Compliant | K5: L3 % | L5: Overall Compliant | M5: Overall %
A6: V1 – Encoding and Sanitization | B6: 30 | C6: 8 | D6: =COUNTIFS('V1 - Encoding and Sanitization'!$F$2:$F$36,"Compliant",'V1 - Encoding and Sanitization'!$E$2:$E$36,1) -> 1 | E6: =IF(C6=0,"",D6/C6) -> 0.125 | F6: 19 | G6: =COUNTIFS('V1 - Encoding and Sanitization'!$F$2:$F$36,"Compliant",'V1 - Encoding and Sanitization'!$E$2:$E$36,2) -> 1 | H6: =IF(F6=0,"",G6/F6) -> 0.052631579 | I6: 3 | J6: =COUNTIFS('V1 - Encoding and Sanitization'!$F$2:$F$36,"Compliant",'V1 - Encoding and Sanitization'!$E$2:$E$36,3) -> 1 | K6: =IF(I6=0,"",J6/I6) -> 0.33333333 | L6: =COUNTIF('V1 - Encoding and Sanitization'!$F$2:$F$36,"Compliant") -> 3 | M6: =IF(B6=0,"",L6/B6) -> 0.1
A7: V2 – Validation and Business Logic | B7: 13 | C7: 4 | D7: =COUNTIFS('V2 - Validation and Business Lo'!$F$2:$F$18,"Compliant",'V2 - Validation and Business Lo'!$E$2:$E$18,1) -> 1 | E7: =IF(C7=0,"",D7/C7) -> 0.25 | F7: 7 | G7: =COUNTIFS('V2 - Validation and Business Lo'!$F$2:$F$18,"Compliant",'V2 - Validation and Business Lo'!$E$2:$E$18,2) -> 0 | H7: =IF(F7=0,"",G7/F7) -> 0 | I7: 2 | J7: =COUNTIFS('V2 - Validation and Business Lo'!$F$2:$F$18,"Compliant",'V2 - Validation and Business Lo'!$E$2:$E$18,3) -> 0 | K7: =IF(I7=0,"",J7/I7) -> 0 | L7: =COUNTIF('V2 - Validation and Business Lo'!$F$2:$F$18,"Compliant") -> 1 | M7: =IF(B7=0,"",L7/B7) -> 0.076923077
A8: V3 – Web Frontend Security | B8: 31 | C8: 8 | D8: =COUNTIFS('V3 - Web Frontend Security'!$F$2:$F$39,"Compliant",'V3 - Web Frontend Security'!$E$2:$E$39,1) -> 1 | E8: =IF(C8=0,"",D8/C8) -> 0.125 | F8: 11 | G8: =COUNTIFS('V3 - Web Frontend Security'!$F$2:$F$39,"Compliant",'V3 - Web Frontend Security'!$E$2:$E$39,2) -> 4 | H8: =IF(F8=0,"",G8/F8) -> 0.36363636 | I8: 12 | J8: =COUNTIFS('V3 - Web Frontend Security'!$F$2:$F$39,"Compliant",'V3 - Web Frontend Security'!$E$2:$E$39,3) -> 1 | K8: =IF(I8=0,"",J8/I8) -> 0.083333333 | L8: =COUNTIF('V3 - Web Frontend Security'!$F$2:$F$39,"Compliant") -> 6 | M8: =IF(B8=0,"",L8/B8) -> 0.19354839
A9: V4 – API and Web Service | B9: 16 | C9: 2 | D9: =COUNTIFS('V4 - API and Web Service'!$F$2:$F$21,"Compliant",'V4 - API and Web Service'!$E$2:$E$21,1) -> 0 | E9: =IF(C9=0,"",D9/C9) -> 0 | F9: 8 | G9: =COUNTIFS('V4 - API and Web Service'!$F$2:$F$21,"Compliant",'V4 - API and Web Service'!$E$2:$E$21,2) -> 0 | H9: =IF(F9=0,"",G9/F9) -> 0 | I9: 6 | J9: =COUNTIFS('V4 - API and Web Service'!$F$2:$F$21,"Compliant",'V4 - API and Web Service'!$E$2:$E$21,3) -> 0 | K9: =IF(I9=0,"",J9/I9) -> 0 | L9: =COUNTIF('V4 - API and Web Service'!$F$2:$F$21,"Compliant") -> 0 | M9: =IF(B9=0,"",L9/B9) -> 0
A10: V5 – File Handling | B10: 13 | C10: 4 | D10: =COUNTIFS('V5 - File Handling'!$F$2:$F$18,"Compliant",'V5 - File Handling'!$E$2:$E$18,1) -> 4 | E10: =IF(C10=0,"",D10/C10) -> 1 | F10: 5 | G10: =COUNTIFS('V5 - File Handling'!$F$2:$F$18,"Compliant",'V5 - File Handling'!$E$2:$E$18,2) -> 2 | H10: =IF(F10=0,"",G10/F10) -> 0.4 | I10: 4 | J10: =COUNTIFS('V5 - File Handling'!$F$2:$F$18,"Compliant",'V5 - File Handling'!$E$2:$E$18,3) -> 1 | K10: =IF(I10=0,"",J10/I10) -> 0.25 | L10: =COUNTIF('V5 - File Handling'!$F$2:$F$18,"Compliant") -> 7 | M10: =IF(B10=0,"",L10/B10) -> 0.53846154
A11: V6 – Authentication | B11: 47 | C11: 13 | D11: =COUNTIFS('V6 - Authentication'!$F$2:$F$56,"Compliant",'V6 - Authentication'!$E$2:$E$56,1) -> 4 | E11: =IF(C11=0,"",D11/C11) -> 0.30769231 | F11: 22 | G11: =COUNTIFS('V6 - Authentication'!$F$2:$F$56,"Compliant",'V6 - Authentication'!$E$2:$E$56,2) -> 1 | H11: =IF(F11=0,"",G11/F11) -> 0.045454545 | I11: 12 | J11: =COUNTIFS('V6 - Authentication'!$F$2:$F$56,"Compliant",'V6 - Authentication'!$E$2:$E$56,3) -> 1 | K11: =IF(I11=0,"",J11/I11) -> 0.083333333 | L11: =COUNTIF('V6 - Authentication'!$F$2:$F$56,"Compliant") -> 6 | M11: =IF(B11=0,"",L11/B11) -> 0.12765957
A12: V7 – Session Management | B12: 19 | C12: 6 | D12: =COUNTIFS('V7 - Session Management'!$F$2:$F$26,"Compliant",'V7 - Session Management'!$E$2:$E$26,1) -> 1 | E12: =IF(C12=0,"",D12/C12) -> 0.16666667 | F12: 12 | G12: =COUNTIFS('V7 - Session Management'!$F$2:$F$26,"Compliant",'V7 - Session Management'!$E$2:$E$26,2) -> 1 | H12: =IF(F12=0,"",G12/F12) -> 0.083333333 | I12: 1 | J12: =COUNTIFS('V7 - Session Management'!$F$2:$F$26,"Compliant",'V7 - Session Management'!$E$2:$E$26,3) -> 0 | K12: =IF(I12=0,"",J12/I12) -> 0 | L12: =COUNTIF('V7 - Session Management'!$F$2:$F$26,"Compliant") -> 2 | M12: =IF(B12=0,"",L12/B12) -> 0.10526316
A13: V8 – Authorization | B13: 13 | C13: 4 | D13: =COUNTIFS('V8 - Authorization'!$F$2:$F$18,"Compliant",'V8 - Authorization'!$E$2:$E$18,1) -> 3 | E13: =IF(C13=0,"",D13/C13) -> 0.75 | F13: 3 | G13: =COUNTIFS('V8 - Authorization'!$F$2:$F$18,"Compliant",'V8 - Authorization'!$E$2:$E$18,2) -> 0 | H13: =IF(F13=0,"",G13/F13) -> 0 | I13: 6 | J13: =COUNTIFS('V8 - Authorization'!$F$2:$F$18,"Compliant",'V8 - Authorization'!$E$2:$E$18,3) -> 1 | K13: =IF(I13=0,"",J13/I13) -> 0.16666667 | L13: =COUNTIF('V8 - Authorization'!$F$2:$F$18,"Compliant") -> 4 | M13: =IF(B13=0,"",L13/B13) -> 0.30769231
A14: V9 – Self-contained Tokens | B14: 7 | C14: 4 | D14: =COUNTIFS('V9 - Self-contained Tokens'!$F$2:$F$10,"Compliant",'V9 - Self-contained Tokens'!$E$2:$E$10,1) -> 1 | E14: =IF(C14=0,"",D14/C14) -> 0.25 | F14: 3 | G14: =COUNTIFS('V9 - Self-contained Tokens'!$F$2:$F$10,"Compliant",'V9 - Self-contained Tokens'!$E$2:$E$10,2) -> 0 | H14: =IF(F14=0,"",G14/F14) -> 0 | I14: 0 | J14: N/A | K14: N/A | L14: =COUNTIF('V9 - Self-contained Tokens'!$F$2:$F$10,"Compliant") -> 1 | M14: =IF(B14=0,"",L14/B14) -> 0.14285714
A15: V10 – OAuth and OIDC | B15: 36 | C15: 5 | D15: =COUNTIFS('V10 - OAuth and OIDC'!$F$2:$F$44,"Compliant",'V10 - OAuth and OIDC'!$E$2:$E$44,1) -> 0 | E15: =IF(C15=0,"",D15/C15) -> 0 | F15: 24 | G15: =COUNTIFS('V10 - OAuth and OIDC'!$F$2:$F$44,"Compliant",'V10 - OAuth and OIDC'!$E$2:$E$44,2) -> 0 | H15: =IF(F15=0,"",G15/F15) -> 0 | I15: 7 | J15: =COUNTIFS('V10 - OAuth and OIDC'!$F$2:$F$44,"Compliant",'V10 - OAuth and OIDC'!$E$2:$E$44,3) -> 0 | K15: =IF(I15=0,"",J15/I15) -> 0 | L15: =COUNTIF('V10 - OAuth and OIDC'!$F$2:$F$44,"Compliant") -> 0 | M15: =IF(B15=0,"",L15/B15) -> 0
A16: V11 – Cryptography | B16: 24 | C16: 3 | D16: =COUNTIFS('V11 - Cryptography'!$F$2:$F$32,"Compliant",'V11 - Cryptography'!$E$2:$E$32,1) -> 1 | E16: =IF(C16=0,"",D16/C16) -> 0.33333333 | F16: 11 | G16: =COUNTIFS('V11 - Cryptography'!$F$2:$F$32,"Compliant",'V11 - Cryptography'!$E$2:$E$32,2) -> 3 | H16: =IF(F16=0,"",G16/F16) -> 0.27272727 | I16: 10 | J16: =COUNTIFS('V11 - Cryptography'!$F$2:$F$32,"Compliant",'V11 - Cryptography'!$E$2:$E$32,3) -> 0 | K16: =IF(I16=0,"",J16/I16) -> 0 | L16: =COUNTIF('V11 - Cryptography'!$F$2:$F$32,"Compliant") -> 4 | M16: =IF(B16=0,"",L16/B16) -> 0.16666667
A17: V12 – Secure Communication | B17: 12 | C17: 3 | D17: =COUNTIFS('V12 - Secure Communication'!$F$2:$F$16,"Compliant",'V12 - Secure Communication'!$E$2:$E$16,1) -> 0 | E17: =IF(C17=0,"",D17/C17) -> 0 | F17: 6 | G17: =COUNTIFS('V12 - Secure Communication'!$F$2:$F$16,"Compliant",'V12 - Secure Communication'!$E$2:$E$16,2) -> 0 | H17: =IF(F17=0,"",G17/F17) -> 0 | I17: 3 | J17: =COUNTIFS('V12 - Secure Communication'!$F$2:$F$16,"Compliant",'V12 - Secure Communication'!$E$2:$E$16,3) -> 0 | K17: =IF(I17=0,"",J17/I17) -> 0 | L17: =COUNTIF('V12 - Secure Communication'!$F$2:$F$16,"Compliant") -> 0 | M17: =IF(B17=0,"",L17/B17) -> 0
A18: V13 – Configuration | B18: 21 | C18: 1 | D18: =COUNTIFS('V13 - Configuration'!$F$2:$F$26,"Compliant",'V13 - Configuration'!$E$2:$E$26,1) -> 0 | E18: =IF(C18=0,"",D18/C18) -> 0 | F18: 12 | G18: =COUNTIFS('V13 - Configuration'!$F$2:$F$26,"Compliant",'V13 - Configuration'!$E$2:$E$26,2) -> 1 | H18: =IF(F18=0,"",G18/F18) -> 0.083333333 | I18: 8 | J18: =COUNTIFS('V13 - Configuration'!$F$2:$F$26,"Compliant",'V13 - Configuration'!$E$2:$E$26,3) -> 0 | K18: =IF(I18=0,"",J18/I18) -> 0 | L18: =COUNTIF('V13 - Configuration'!$F$2:$F$26,"Compliant") -> 1 | M18: =IF(B18=0,"",L18/B18) -> 0.047619048
A19: V14 – Data Protection | B19: 13 | C19: 2 | D19: =COUNTIFS('V14 - Data Protection'!$F$2:$F$17,"Compliant",'V14 - Data Protection'!$E$2:$E$17,1) -> 0 | E19: =IF(C19=0,"",D19/C19) -> 0 | F19: 7 | G19: =COUNTIFS('V14 - Data Protection'!$F$2:$F$17,"Compliant",'V14 - Data Protection'!$E$2:$E$17,2) -> 1 | H19: =IF(F19=0,"",G19/F19) -> 0.14285714 | I19: 4 | J19: =COUNTIFS('V14 - Data Protection'!$F$2:$F$17,"Compliant",'V14 - Data Protection'!$E$2:$E$17,3) -> 0 | K19: =IF(I19=0,"",J19/I19) -> 0 | L19: =COUNTIF('V14 - Data Protection'!$F$2:$F$17,"Compliant") -> 1 | M19: =IF(B19=0,"",L19/B19) -> 0.076923077
A20: V15 – Secure Coding and Architecture | B20: 21 | C20: 3 | D20: =COUNTIFS('V15 - Secure Coding and Archite'!$F$2:$F$26,"Compliant",'V15 - Secure Coding and Archite'!$E$2:$E$26,1) -> 0 | E20: =IF(C20=0,"",D20/C20) -> 0 | F20: 10 | G20: =COUNTIFS('V15 - Secure Coding and Archite'!$F$2:$F$26,"Compliant",'V15 - Secure Coding and Archite'!$E$2:$E$26,2) -> 1 | H20: =IF(F20=0,"",G20/F20) -> 0.1 | I20: 8 | J20: =COUNTIFS('V15 - Secure Coding and Archite'!$F$2:$F$26,"Compliant",'V15 - Secure Coding and Archite'!$E$2:$E$26,3) -> 1 | K20: =IF(I20=0,"",J20/I20) -> 0.125 | L20: =COUNTIF('V15 - Secure Coding and Archite'!$F$2:$F$26,"Compliant") -> 2 | M20: =IF(B20=0,"",L20/B20) -> 0.095238095
A21: V16 – Security Logging and Error Handling | B21: 17 | C21: 0 | D21: N/A | E21: N/A | F21: 16 | G21: =COUNTIFS('V16 - Security Logging and Erro'!$F$2:$F$23,"Compliant",'V16 - Security Logging and Erro'!$E$2:$E$23,2) -> 3 | H21: =IF(F21=0,"",G21/F21) -> 0.1875 | I21: 1 | J21: =COUNTIFS('V16 - Security Logging and Erro'!$F$2:$F$23,"Compliant",'V16 - Security Logging and Erro'!$E$2:$E$23,3) -> 1 | K21: =IF(I21=0,"",J21/I21) -> 1 | L21: =COUNTIF('V16 - Security Logging and Erro'!$F$2:$F$23,"Compliant") -> 4 | M21: =IF(B21=0,"",L21/B21) -> 0.23529412
A22: V17 – WebRTC | B22: 12 | C22: 0 | D22: N/A | E22: N/A | F22: 7 | G22: =COUNTIFS('V17 - WebRTC'!$F$2:$F$16,"Compliant",'V17 - WebRTC'!$E$2:$E$16,2) -> 0 | H22: =IF(F22=0,"",G22/F22) -> 0 | I22: 5 | J22: =COUNTIFS('V17 - WebRTC'!$F$2:$F$16,"Compliant",'V17 - WebRTC'!$E$2:$E$16,3) -> 0 | K22: =IF(I22=0,"",J22/I22) -> 0 | L22: =COUNTIF('V17 - WebRTC'!$F$2:$F$16,"Compliant") -> 0 | M22: =IF(B22=0,"",L22/B22) -> 0
A23: TOTAL | B23: =SUM(B6:B22) -> 345 | C23: =SUM(C6:C22) -> 70 | D23: =SUM(D6:D22) -> 17 | E23: =IFERROR(AVERAGE(E6:E22),"") -> 0.22051282 | F23: =SUM(F6:F22) -> 183 | G23: =SUM(G6:G22) -> 18 | H23: =IFERROR(AVERAGE(H6:H22),"") -> 0.10185139 | I23: =SUM(I6:I22) -> 92 | J23: =SUM(J6:J22) -> 7 | K23: =IFERROR(AVERAGE(K6:K22),"") -> 0.12760417 | L23: =SUM(L6:L22) -> 42 | M23: =IFERROR(AVERAGE(M6:M22),"") -> 0.13024389

Sheet Assessment Notes
A1: Assessment methodology
A3: Scope
A4: Filled conservatively from the uploaded Phase 1 documents only.
A5: GhostReport is treated as a backend-focused whistleblowing API with anonymous reporting, internal staff auth, file upload/storage, and logging.
A7: Status logic
A8: Compliant = explicitly supported by the uploaded docs.
A9: In Progress = clearly relevant / planned, but implementation or config detail is still missing.
A10: Not Applicable = out of scope for this backend-only deliverable (for example OAuth/OIDC, WebRTC, many browser-only controls).
A12: Important note about the template
A13: The Summary sheet counts all requirements, so Not Applicable rows still reduce the displayed percentages.
A15: Primary sources used
A16: DESOFS - Phase 1.docx
A17: Project.pdf

Sheet V1 - Encoding and Sanitization
A1: Section ID | B1: Section Name | C1: Req ID | D1: Description | E1: Level | F1: Status | G1: Observations | H1: Reference / Link
A2: V1.1 | B2: Encoding and Sanitization Architecture
A3: V1.1 | B3: Encoding and Sanitization Architecture | C3: V1.1.1 | D3: Verify that input is decoded or unescaped into a canonical form only once, it is only decoded when encoded data in that form is expected, and that this is done before processing the input further, for example it is not performed after input validation or sanitization. | E3: 2 | F3: In Progress | G3: Partial canonicalization exists for file paths and tracking codes, but DTO input normalization is not consistently enforced or tested. | H3: FileStorageService.java; SafeFilename.java; TrackingCode.java; ReportDescription.java; FileStorageServiceTest
A4: V1.1 | B4: Encoding and Sanitization Architecture | C4: V1.1.2 | D4: Verify that the application performs output encoding and escaping either as a final step before being used by the interpreter for which it is intended or by the interpreter itself. | E4: 2 | F4: In Progress | G4: Output escaping is partial: Jackson and newer backoffice pages escape values, but public pages still render unescaped API data. | H4: admin.html; analyst.html; auditor.html; submit.html; track.html; js/api.js
A5: V1.2 | B5: Injection Prevention
A6: V1.2 | B6: Injection Prevention | C6: V1.2.1 | D6: Verify that output encoding for an HTTP response, HTML document, or XML document is relevant for the context required, such as encoding the relevant characters for HTML elements, HTML attributes, HTML comments, CSS, or HTTP header fields, to avoid changing the message or document structure. | E6: 1 | F6: In Progress | G6: HTML output encoding is relevant and partially implemented, but public pages still have unescaped DOM rendering paths. | H6: track.html; submit.html; js/api.js; admin.html; analyst.html; auditor.html
A7: V1.2 | B7: Injection Prevention | C7: V1.2.2 | D7: Verify that when dynamically building URLs, untrusted data is encoded according to its context (e.g., URL encoding or base64url encoding for query or path parameters). Ensure that only safe URL protocols are permitted (e.g., disallow javascript: or data:). | E7: 1 | F7: In Progress | G7: Safe URL construction is partial; backup URLs are encoded, but not all dynamic query/path values are encoded consistently. | H7: admin.html; auditor.html; submit.html; AdminBackupController.java; ReportService.java
A8: V1.2 | B8: Injection Prevention | C8: V1.2.3 | D8: Verify that output encoding or escaping is used when dynamically building JavaScript content (including JSON), to avoid changing the message or document structure (to avoid JavaScript and JSON injection). | E8: 1 | F8: In Progress | G8: JSON serialization is framework-based, but JavaScript/DOM output escaping remains incomplete in frontend static files. | H8: JwtService.java; BackupService.java; analyst.html; submit.html; track.html; js/api.js
A9: V1.2 | B9: Injection Prevention | C9: V1.2.4 | D9: Verify that data selection or database queries (e.g., SQL, HQL, NoSQL, Cypher) use parameterized queries, ORMs, entity frameworks, or are otherwise protected from SQL Injection and other database injection attacks. This is also relevant when writing stored procedures. | E9: 1 | F9: Compliant | G9: Database access uses Spring Data/JPA derived methods and bound JPQL; no dynamic SQL/HQL concatenation was found. | H9: ReportRepository.java; UserRepository.java; DatabaseConstraintInitializer.java; pom.xml
A10: V1.2 | B10: Injection Prevention | C10: V1.2.5 | D10: Verify that the application protects against OS command injection and that operating system calls use parameterized OS queries or use contextual command line output encoding. | E10: 1 | F10: In Progress | G10: No OS command execution exists in the current implementation; file and backup operations use Java APIs. | H10: N/A – no OS command execution in current Sprint 1 scope
A11: V1.2 | B11: Injection Prevention | C11: V1.2.6 | D11: Verify that the application protects against LDAP injection vulnerabilities, or that specific security controls to prevent LDAP injection have been implemented. | E11: 2 | F11: Not Applicable | G11: Not applicable in the current system design. | H11: N/A – not in current system scope
A12: V1.2 | B12: Injection Prevention | C12: V1.2.7 | D12: Verify that the application is protected against XPath injection attacks by using query parameterization or precompiled queries. | E12: 2 | F12: Not Applicable | G12: Not applicable in the current system design. | H12: N/A – not in current system scope
A13: V1.2 | B13: Injection Prevention | C13: V1.2.8 | D13: Verify that LaTeX processors are configured securely (such as not using the "--shell-escape" flag) and an allowlist of commands is used to prevent LaTeX injection attacks. | E13: 2 | F13: Not Applicable | G13: Not applicable in the current system design. | H13: N/A – not in current system scope
A14: V1.2 | B14: Injection Prevention | C14: V1.2.9 | D14: Verify that the application escapes special characters in regular expressions (typically using a backslash) to prevent them from being misinterpreted as metacharacters. | E14: 2 | F14: In Progress | G14: Regex use appears limited to fixed validation patterns, but explicit ReDoS/regex safety tests are not yet documented. | H14: TrackingCode.java; BackupService.java; CreateUserRequest.java
A15: V1.2 | B15: Injection Prevention | C15: V1.2.10 | D15: Verify that the application is protected against CSV and Formula Injection. The application must follow the escaping rules defined in RFC 4180 sections 2.6 and 2.7 when exporting CSV content. Additionally, when exporting to CSV or other spreadsheet formats (such as XLS, XLSX, or ODF), special characters (including '=', '+', '-', '@', '\t' (tab), and '\0' (null character)) must be escaped with a single quote if they appear as the first character in a field value. | E15: 3 | F15: Not Started | G15: CSV/spreadsheet export protection is not implemented or specified. If CSV/XLSX/ODS export is introduced, dangerous leading characters must be escaped. | H15: Project.pdf: backend API, 3 roles, OS/file ops, ASVS deliverable
A16: V1.3 | B16: Sanitization
A17: V1.3 | B17: Sanitization | C17: V1.3.1 | D17: Verify that all untrusted HTML input from WYSIWYG editors or similar is sanitized using a well-known and secure HTML sanitization library or framework feature. | E17: 1 | F17: Not Applicable | G17: Not applicable in the current system design. | H17: N/A – not in current system scope
A18: V1.3 | B18: Sanitization | C18: V1.3.2 | D18: Verify that the application avoids the use of eval() or other dynamic code execution features such as Spring Expression Language (SpEL). Where there is no alternative, any user input being included must be sanitized before being executed. | E18: 1 | F18: Not Applicable | G18: No eval, dynamic code execution, or user-controlled SpEL usage was implemented. | H18: N/A – no dynamic code execution in current Sprint 1 scope
A19: V1.3 | B19: Sanitization | C19: V1.3.3 | D19: Verify that data being passed to a potentially dangerous context is sanitized beforehand to enforce safety measures, such as only allowing characters which are safe for this context and trimming input which is too long. | E19: 2 | F19: In Progress | G19: Context-specific sanitization exists for files, ZIP entries, and logs, but frontend rendering and manual JSON paths need hardening. | H19: FileStorageService.java; BackupService.java; CasePackageService.java; AuditLogService.java; SecurityMonitoringService.java
A20: V1.3 | B20: Sanitization | C20: V1.3.4 | D20: Verify that user-supplied Scalable Vector Graphics (SVG) scriptable content is validated or sanitized to contain only tags and attributes (such as draw graphics) that are safe for the application, e.g., do not contain scripts and foreignObject. | E20: 2 | F20: Not Applicable | G20: Not applicable in the current system design. | H20: N/A – not in current system scope
A21: V1.3 | B21: Sanitization | C21: V1.3.5 | D21: Verify that the application sanitizes or disables user-supplied scriptable or expression template language content, such as Markdown, CSS or XSL stylesheets, BBCode, or similar. | E21: 2 | F21: Not Applicable | G21: Not applicable in the current system design. | H21: N/A – not in current system scope
A22: V1.3 | B22: Sanitization | C22: V1.3.6 | D22: Verify that the application protects against Server-side Request Forgery (SSRF) attacks, by validating untrusted data against an allowlist of protocols, domains, paths and ports and sanitizing potentially dangerous characters before using the data to call another service. | E22: 2 | F22: Not Applicable | G22: Backend SSRF surface is not present because the application does not make outbound HTTP requests from user input. | H22: N/A – no outbound HTTP requests from user input
A23: V1.3 | B23: Sanitization | C23: V1.3.7 | D23: Verify that the application protects against template injection attacks by not allowing templates to be built based on untrusted input. Where there is no alternative, any untrusted input being included dynamically during template creation must be sanitized or strictly validated. | E23: 2 | F23: Not Applicable | G23: Server-side template rendering is not implemented, so template injection is not in scope. | H23: pom.xml; src/main/resources/static/*
A24: V1.3 | B24: Sanitization | C24: V1.3.8 | D24: Verify that the application appropriately sanitizes untrusted input before use in Java Naming and Directory Interface (JNDI) queries and that JNDI is configured securely to prevent JNDI injection attacks. | E24: 2 | F24: Not Applicable | G24: Not applicable in the current system design. | H24: N/A – not in current system scope
A25: V1.3 | B25: Sanitization | C25: V1.3.9 | D25: Verify that the application sanitizes content before it is sent to memcache to prevent injection attacks. | E25: 2 | F25: Not Applicable | G25: Not applicable in the current system design. | H25: N/A – not in current system scope
A26: V1.3 | B26: Sanitization | C26: V1.3.10 | D26: Verify that format strings which might resolve in an unexpected or malicious way when used are sanitized before being processed. | E26: 2 | F26: Compliant | G26: Format strings are fixed in code; user-controlled data is not used as the format template. | H26: FileStorageService.java; CasePackageService.java; tests using fixed .formatted() payloads
A27: V1.3 | B27: Sanitization | C27: V1.3.11 | D27: Verify that the application sanitizes user input before passing to mail systems to protect against SMTP or IMAP injection. | E27: 2 | F27: Not Applicable | G27: Not applicable in the current system design. | H27: N/A – not in current system scope
A28: V1.3 | B28: Sanitization | C28: V1.3.12 | D28: Verify that regular expressions are free from elements causing exponential backtracking, and ensure untrusted input is sanitized to mitigate ReDoS or Runaway Regex attacks. | E28: 3 | F28: Compliant | G28: Existing regex use is fixed and not dynamically built from user input; no ReDoS-prone patterns were found. | H28: TrackingCode.java; BackupService.java; CreateUserRequest.java
A29: V1.4 | B29: Memory, String, and Unmanaged Code
A30: V1.4 | B30: Memory, String, and Unmanaged Code | C30: V1.4.1 | D30: Verify that the application uses memory-safe string, safer memory copy and pointer arithmetic to detect or prevent stack, buffer, or heap overflows. | E30: 2 | F30: Not Applicable | G30: Not applicable in the current system design. | H30: N/A – not in current system scope
A31: V1.4 | B31: Memory, String, and Unmanaged Code | C31: V1.4.2 | D31: Verify that sign, range, and input validation techniques are used to prevent integer overflows. | E31: 2 | F31: Not Applicable | G31: Not applicable in the current system design. | H31: N/A – not in current system scope
A32: V1.4 | B32: Memory, String, and Unmanaged Code | C32: V1.4.3 | D32: Verify that dynamically allocated memory and resources are released, and that references or pointers to freed memory are removed or set to null to prevent dangling pointers and use-after-free vulnerabilities. | E32: 2 | F32: Not Applicable | G32: Not applicable in the current system design. | H32: N/A – not in current system scope
A33: V1.5 | B33: Safe Deserialization
A34: V1.5 | B34: Safe Deserialization | C34: V1.5.1 | D34: Verify that the application configures XML parsers to use a restrictive configuration and that unsafe features such as resolving external entities are disabled to prevent XML eXternal Entity (XXE) attacks. | E34: 1 | F34: Not Applicable | G34: XML parsing is not implemented, so XXE parser configuration is outside current scope. | H34: N/A – no XML parser/input processing in current Sprint 1 scope
A35: V1.5 | B35: Safe Deserialization | C35: V1.5.2 | D35: Verify that deserialization of untrusted data enforces safe input handling, such as using an allowlist of object types or restricting client-defined object types, to prevent deserialization attacks. Deserialization mechanisms that are explicitly defined as insecure must not be used with untrusted input. | E35: 2 | F35: In Progress | G35: No arbitrary Java deserialization was found, but JSON/JWT/backup parsing lacks explicit hardening tests and size controls. | H35: JwtService.java; BackupService.java; CasePackageService.java; pom.xml
A36: V1.5 | B36: Safe Deserialization | C36: V1.5.3 | D36: Verify that different parsers used in the application for the same data type (e.g., JSON parsers, XML parsers, URL parsers), perform parsing in a consistent way and use the same character encoding mechanism to avoid issues such as JSON Interoperability vulnerabilities or different URI or file parsing behavior being exploited in Remote File Inclusion (RFI) or Server-side Request Forgery (SSRF) attacks. | E36: 3 | F36: In Progress | G36: Parser and encoding consistency is partial; standard parsers are used, but manual JSON and raw URL construction remain. | H36: CasePackageService.java; JwtService.java; submit.html; track.html; AdminBackupController.java

Sheet V2 - Validation and Business Lo
A1: Section ID | B1: Section Name | C1: Req ID | D1: Description | E1: Level | F1: Status | G1: Observations | H1: Reference / Link
A2: V2.1 | B2: Validation and Business Logic Documentation
A3: V2.1 | B3: Validation and Business Logic Documentation | C3: V2.1.1 | D3: Verify that the application's documentation defines input validation rules for how to check the validity of data items against an expected structure. This could be common data formats such as credit card numbers, email addresses, telephone numbers, or it could be an internal data format. | E3: 1 | F3: In Progress | G3: Documentation names validation and upload controls, but complete field-level validation rules for all request DTOs and path inputs are not documented. | H3: README.md; application.yaml; CreateReportRequest.java; CreateUserRequest.java; FileStorageService.java
A4: V2.1 | B4: Validation and Business Logic Documentation | C4: V2.1.2 | D4: Verify that the application's documentation defines how to validate the logical and contextual consistency of combined data items, such as checking that suburb and ZIP code match. | E4: 2 | F4: In Progress | G4: Some contextual rules are visible in code and tests, but documentation does not fully define cross-field consistency rules such as report ID plus tracking code, case ownership, or closed-case package rules. | H4: README.md; ReportService.java; CaseReviewService.java; CasePackageServiceIntegrationTest; AnalystCaseOwnershipTest
A5: V2.1 | B5: Validation and Business Logic Documentation | C5: V2.1.3 | D5: Verify that expectations for business logic limits and validations are documented, including both per-user and globally across the application. | E5: 2 | F5: In Progress | G5: Business limits are partially documented/configured for uploads, rate limits, backups, and roles, but global quotas and all per-user limits are not fully specified. | H5: README.md; application.yaml; RateLimitProperties.java; FileStorageService.java
A6: V2.2 | B6: Input Validation
A7: V2.2 | B7: Input Validation | C7: V2.2.1 | D7: Verify that input is validated to enforce business or functional expectations for that input. This should either use positive validation against an allow list of values, patterns, and ranges, or be based on comparing the input to an expected structure and logical limits according to predefined rules. For L1, this can focus on input which is used to make specific business or security decisions. For L2 and up, this should apply to all input. | E7: 1 | F7: In Progress | G7: Backend validation exists through Bean Validation, enums, value objects, file allowlists, size checks, and path checks, but some inputs still only have minimal NotBlank/null validation. | H7: CreateReportRequest.java; CreateUserRequest.java; TrackingCode.java; ReportDescription.java; SafeFilename.java; FileStorageService.java
A8: V2.2 | B8: Input Validation | C8: V2.2.2 | D8: Verify that the application is designed to enforce input validation at a trusted service layer. While client-side validation improves usability and should be encouraged, it must not be relied upon as a security control. | E8: 1 | F8: Compliant | G8: Validation is enforced in controllers and services using @Valid, domain validation, service-level business checks, and repository/model constraints, not only in static frontend JavaScript. | H8: ReportController.java; AdminController.java; ReportService.java; CaseReviewService.java; FileStorageService.java; PublicReportFlowIntegrationTest; ReportControllerAttachmentUploadTest
A9: V2.2 | B9: Input Validation | C9: V2.2.3 | D9: Verify that the application ensures that combinations of related data items are reasonable according to the pre-defined rules. | E9: 2 | F9: In Progress | G9: Related data combinations are partially validated, including tracking code with report/attachment, analyst ownership, closed-case package generation, and backup filename rules, but status transition rules are incomplete. | H9: ReportService.java; CaseReviewService.java; CasePackageService.java; BackupService.java; AnalystCaseOwnershipTest; ClosedCaseSecurityTest
A10: V2.3 | B10: Business Logic Security
A11: V2.3 | B11: Business Logic Security | C11: V2.3.1 | D11: Verify that the application will only process business logic flows for the same user in the expected sequential step order and without skipping steps. | E11: 1 | F11: In Progress | G11: Workflow sequencing is partially enforced: uploads require an existing report and matching tracking code, case packages require closed cases, and backup restore verifies integrity first, but report status changes can skip states. | H11: ReportService.java; CaseReviewService.java; CasePackageService.java; BackupService.java; PublicReportFlowIntegrationTest; CasePackageServiceIntegrationTest; BackupServiceIntegrationTest
A12: V2.3 | B12: Business Logic Security | C12: V2.3.2 | D12: Verify that business logic limits are implemented per the application's documentation to avoid business logic flaws being exploited. | E12: 2 | F12: In Progress | G12: Some business limits are implemented for file size/type, rate-limited tracking/upload/download, backup filename format, and closed-case immutability, but report creation, login, listing, backup frequency, and attachment count limits are incomplete. | H12: RateLimiterService.java; application.yaml; FileStorageService.java; BackupService.java; ClosedCaseSecurityTest; RateLimiterServiceTest
A13: V2.3 | B13: Business Logic Security | C13: V2.3.3 | D13: Verify that transactions are being used at the business logic level such that either a business logic operation succeeds in its entirety or it is rolled back to the previous correct state. | E13: 2 | F13: In Progress | G13: Only read-only audit retrieval has @Transactional; write workflows combine database and file operations without explicit service-level transaction boundaries or rollback guarantees. | H13: AuditReadService.java; ReportService.java; FileStorageService.java; BackupService.java; CasePackageService.java
A14: V2.3 | B14: Business Logic Security | C14: V2.3.4 | D14: Verify that business logic level locking mechanisms are used to ensure that limited quantity resources (such as theater seats or delivery slots) cannot be double-booked by manipulating the application's logic. | E14: 2 | F14: In Progress | G14: Not applicable in the current system design. | H14: N/A – not in current system scope
A15: V2.3 | B15: Business Logic Security | C15: V2.3.5 | D15: Verify that high-value business logic flows require multi-user approval to prevent unauthorized or accidental actions. This could include but is not limited to large monetary transfers, contract approvals, access to classified information, or safety overrides in manufacturing. | E15: 3 | F15: Not Started | G15: High-impact flows such as admin user creation, backup creation/download/restore, and evidence package generation are controlled by RBAC but have no multi-user approval workflow. | H15: AdminController.java; AdminBackupController.java; CasePackageService.java; SecurityConfig.java; AdminBackupControllerSecurityTest; AuditorAuthorizationTest
A16: V2.4 | B16: Anti-automation
A17: V2.4 | B17: Anti-automation | C17: V2.4.1 | D17: Verify that anti-automation controls are in place to protect against excessive calls to application functions that could lead to data exfiltration, garbage-data creation, quota exhaustion, rate-limit breaches, denial-of-service, or overuse of costly resources. | E17: 2 | F17: In Progress | G17: Rate limiting and abuse monitoring exist for tracking verification, uploads, and downloads, but not for report submission, login, audit listing, backup operations, or broader data exfiltration paths. | H17: RateLimiterService.java; ReportController.java; SecurityMonitoringService.java; application.yaml; RateLimiterServiceTest; TrackingCodeEnumerationTest
A18: V2.4 | B18: Anti-automation | C18: V2.4.2 | D18: Verify that business logic flows require realistic human timing, preventing excessively rapid transaction submissions. | E18: 3 | F18: In Progress | G18: Rate limiting provides partial rapid-call throttling for selected public endpoints, but there is no CAPTCHA-equivalent, realistic human timing control, or rapid repeated report submission protection. | H18: RateLimiterService.java; ReportController.java; RateLimiterServiceTest; No implementation evidence found for CAPTCHA or human-timing controls

Sheet V3 - Web Frontend Security
A1: Section ID | B1: Section Name | C1: Req ID | D1: Description | E1: Level | F1: Status | G1: Observations | H1: Reference / Link
A2: V3.1 | B2: Web Frontend Security Documentation
A3: V3.1 | B3: Web Frontend Security Documentation | C3: V3.1.1 | D3: Verify that application documentation states the expected security features that browsers using the application must support (such as HTTPS, HTTP Strict Transport Security (HSTS), Content Security Policy (CSP), and other relevant HTTP security mechanisms). It must also define how the application must behave when some of these features are not available (such as warning the user or blocking access). | E3: 3 | F3: In Progress | G3: Documentation mentions HTTPS/TLS, and Spring Security config implements some browser headers, but expected browser security features and fallback behavior are not fully documented. | H3: README.md; SecurityConfig.java; SecurityHeadersTest
A4: V3.2 | B4: Unintended Content Interpretation
A5: V3.2 | B5: Unintended Content Interpretation | C5: V3.2.1 | D5: Verify that security controls are in place to prevent browsers from rendering content or functionality in HTTP responses in an incorrect context (e.g., when an API, a user-uploaded file or other resource is requested directly). Possible controls could include: not serving the content unless HTTP request header fields (such as Sec-Fetch-\*) indicate it is the correct context, using the sandbox directive of the Content-Security-Policy header field or using the attachment disposition type in the Content-Disposition header field. | E5: 1 | F5: In Progress | G5: Downloads use Content-Disposition attachment and nosniff is configured, but protections for all browser rendering contexts and uploaded/API responses are only partially tested. | H5: ReportService.java; AdminBackupController.java; FileStorageService.java; SecurityConfig.java; SecurityHeadersTest
A6: V3.2 | B6: Unintended Content Interpretation | C6: V3.2.2 | D6: Verify that content intended to be displayed as text, rather than rendered as HTML, is handled using safe rendering functions (such as createTextNode or textContent) to prevent unintended execution of content such as HTML or JavaScript. | E6: 1 | F6: In Progress | G6: Static frontend renders API data; some pages escape values or use innerText, but unsafe innerHTML rendering remains in public and legacy frontend code. | H6: submit.html; track.html; js/api.js; admin.html; analyst.html; auditor.html
A7: V3.2 | B7: Unintended Content Interpretation | C7: V3.2.3 | D7: Verify that the application avoids DOM clobbering when using client-side JavaScript by employing explicit variable declarations, performing strict type checking, avoiding storing global variables on the document object, and implementing namespace isolation. | E7: 3 | F7: Not Started | G7: Client-side JavaScript exists, but no explicit DOM clobbering defenses or tests were implemented. | H7: N/A – frontend/browser functionality not in current system scope
A8: V3.3 | B8: Cookie Setup
A9: V3.3 | B9: Cookie Setup | C9: V3.3.1 | D9: Verify that cookies have the 'Secure' attribute set, and if the '\__Host-' prefix is not used for the cookie name, the '__Secure-' prefix must be used for the cookie name. | E9: 1 | F9: Not Applicable | G9: The application uses JWT Bearer tokens in web storage and stateless security, not authentication/session cookies requiring Secure or cookie prefixes. | H9: SecurityConfig.java; AuthService.java; js/api.js; admin.html; analyst.html; auditor.html
A10: V3.3 | B10: Cookie Setup | C10: V3.3.2 | D10: Verify that each cookie's 'SameSite' attribute value is set according to the purpose of the cookie, to limit exposure to user interface redress attacks and browser-based request forgery attacks, commonly known as cross-site request forgery (CSRF). | E10: 2 | F10: Not Applicable | G10: The application does not issue authentication/session cookies, so SameSite cookie configuration is not applicable to the current implementation. | H10: SecurityConfig.java; AuthService.java; static frontend token storage
A11: V3.3 | B11: Cookie Setup | C11: V3.3.3 | D11: Verify that cookies have the '__Host-' prefix for the cookie name unless they are explicitly designed to be shared with other hosts. | E11: 2 | F11: Not Applicable | G11: The application does not issue host-scoped authentication/session cookies, so __Host- cookie prefix requirements are not applicable. | H11: SecurityConfig.java; AuthService.java
A12: V3.3 | B12: Cookie Setup | C12: V3.3.4 | D12: Verify that if the value of a cookie is not meant to be accessible to client-side scripts (such as a session token), the cookie must have the 'HttpOnly' attribute set and the same value (e. g. session token) must only be transferred to the client via the 'Set-Cookie' header field. | E12: 2 | F12: Not Applicable | G12: Sensitive authentication state is not transferred by Set-Cookie; JWT Bearer tokens are handled by JSON responses and Authorization headers. | H12: AuthController.java; AuthService.java; SecurityConfig.java; static frontend files
A13: V3.3 | B13: Cookie Setup | C13: V3.3.5 | D13: Verify that when the application writes a cookie, the cookie name and value length combined are not over 4096 bytes. Overly large cookies will not be stored by the browser and therefore not sent with requests, preventing the user from using application functionality which relies on that cookie. | E13: 3 | F13: Not Applicable | G13: The application does not define application cookies, so cookie name/value length limits are not applicable in the current scope. | H13: N/A – no application authentication/session cookies
A14: V3.4 | B14: Browser Security Mechanism Headers
A15: V3.4 | B15: Browser Security Mechanism Headers | C15: V3.4.1 | D15: Verify that a Strict-Transport-Security header field is included on all responses to enforce an HTTP Strict Transport Security (HSTS) policy. A maximum age of at least 1 year must be defined, and for L2 and up, the policy must apply to all subdomains as well. | E15: 1 | F15: In Progress | G15: HSTS is configured with one-year max-age and includeSubDomains, but tests do not assert HSTS on HTTPS responses. | H15: SecurityConfig.java; SecurityHeadersTest
A16: V3.4 | B16: Browser Security Mechanism Headers | C16: V3.4.2 | D16: Verify that the Cross-Origin Resource Sharing (CORS) Access-Control-Allow-Origin header field is a fixed value by the application, or if the Origin HTTP request header field value is used, it is validated against an allowlist of trusted origins. When 'Access-Control-Allow-Origin: *' needs to be used, verify that the response does not include any sensitive information. | E16: 1 | F16: In Progress | G16: No wildcard CORS configuration was found, but there is no explicit trusted-origin CORS policy or regression test. | H16: DESOFS Phase 1: DFD/trust boundaries §9; STRIDE §10; mitigations §13
A17: V3.4 | B17: Browser Security Mechanism Headers | C17: V3.4.3 | D17: Verify that HTTP responses include a Content-Security-Policy response header field which defines directives to ensure the browser only loads and executes trusted content or resources, in order to limit execution of malicious JavaScript. As a minimum, a global policy must be used which includes the directives object-src 'none' and base-uri 'none' and defines either an allowlist or uses nonces or hashes. For an L3 application, a per-response policy with nonces or hashes must be defined. | E17: 2 | F17: In Progress | G17: CSP is configured with default-src self, object-src none, and frame-ancestors none, but base-uri none is missing and unsafe-inline is allowed. | H17: SecurityConfig.java; No CorsConfigurationSource implemented
A18: V3.4 | B18: Browser Security Mechanism Headers | C18: V3.4.4 | D18: Verify that all HTTP responses contain an 'X-Content-Type-Options: nosniff' header field. This instructs browsers not to use content sniffing and MIME type guessing for the given response, and to require the response's Content-Type header field value to match the destination resource. For example, the response to a request for a style is only accepted if the response's Content-Type is 'text/css'. This also enables the use of the Cross-Origin Read Blocking (CORB) functionality by the browser. | E18: 2 | F18: Compliant | G18: X-Content-Type-Options nosniff is configured through Spring Security and verified by a security header test. | H18: SecurityConfig.java; SecurityHeadersTest.publicPageIncludesSecurityHeaders
A19: V3.4 | B19: Browser Security Mechanism Headers | C19: V3.4.5 | D19: Verify that the application sets a referrer policy to prevent leakage of technically sensitive data to third-party services via the 'Referer' HTTP request header field. This can be done using the Referrer-Policy HTTP response header field or via HTML element attributes. Sensitive data could include path and query data in the URL, and for internal non-public applications also the hostname. | E19: 2 | F19: Compliant | G19: Referrer-Policy is configured as no-referrer and verified by a security header test. | H19: SecurityConfig.java; SecurityHeadersTest.publicPageIncludesSecurityHeaders
A20: V3.4 | B20: Browser Security Mechanism Headers | C20: V3.4.6 | D20: Verify that the web application uses the frame-ancestors directive of the Content-Security-Policy header field for every HTTP response to ensure that it cannot be embedded by default and that embedding of specific resources is allowed only when necessary. Note that the X-Frame-Options header field, although supported by browsers, is obsolete and may not be relied upon. | E20: 2 | F20: Compliant | G20: Clickjacking protection is configured using CSP frame-ancestors none and X-Frame-Options DENY. | H20: SecurityConfig.java; SecurityHeadersTest.publicPageIncludesSecurityHeaders
A21: V3.4 | B21: Browser Security Mechanism Headers | C21: V3.4.7 | D21: Verify that the Content-Security-Policy header field specifies a location to report violations. | E21: 3 | F21: Not Started | G21: CSP violation reporting is not configured. | H21: No implementation evidence found
A22: V3.4 | B22: Browser Security Mechanism Headers | C22: V3.4.8 | D22: Verify that all HTTP responses that initiate a document rendering (such as responses with Content-Type text/html), include the Cross‑Origin‑Opener‑Policy header field with the same-origin directive or the same-origin-allow-popups directive as required. This prevents attacks that abuse shared access to Window objects, such as tabnabbing and frame counting. | E22: 3 | F22: Not Started | G22: Cross-Origin-Opener-Policy is not configured for document-rendering responses. | H22: No implementation evidence found
A23: V3.5 | B23: Browser Origin Separation
A24: V3.5 | B24: Browser Origin Separation | C24: V3.5.1 | D24: Verify that, if the application does not rely on the CORS preflight mechanism to prevent disallowed cross-origin requests to use sensitive functionality, these requests are validated to ensure they originate from the application itself. This may be done by using and validating anti-forgery tokens or requiring extra HTTP header fields that are not CORS-safelisted request-header fields. This is to defend against browser-based request forgery attacks, commonly known as cross-site request forgery (CSRF). | E24: 1 | F24: In Progress | G24: CSRF is disabled and authenticated operations use Bearer Authorization headers, but no Origin, Referer, or Sec-Fetch validation is implemented or documented. | H24: SecurityConfig.java; admin.html; analyst.html; auditor.html
A25: V3.5 | B25: Browser Origin Separation | C25: V3.5.2 | D25: Verify that, if the application relies on the CORS preflight mechanism to prevent disallowed cross-origin use of sensitive functionality, it is not possible to call the functionality with a request which does not trigger a CORS-preflight request. This may require checking the values of the 'Origin' and 'Content-Type' request header fields or using an extra header field that is not a CORS-safelisted header-field. | E25: 1 | F25: Not Applicable | G25: CORS preflight is not used as the protection mechanism for sensitive functionality; protected endpoints rely on Bearer authentication and RBAC. | H25: SecurityConfig.java; JwtAuthenticationFilter.java
A26: V3.5 | B26: Browser Origin Separation | C26: V3.5.3 | D26: Verify that HTTP requests to sensitive functionality use appropriate HTTP methods such as POST, PUT, PATCH, or DELETE, and not methods defined by the HTTP specification as "safe" such as HEAD, OPTIONS, or GET. Alternatively, strict validation of the Sec-Fetch-* request header fields can be used to ensure that the request did not originate from an inappropriate cross-origin call, a navigation request, or a resource load (such as an image source) where this is not expected. | E26: 1 | F26: Compliant | G26: State-changing sensitive operations use POST or PATCH; GET endpoints are used for read-only listing, verification, manifest, and download operations. | H26: ReportController.java; AnalystController.java; AdminController.java; AdminBackupController.java; AuditController.java
A27: V3.5 | B27: Browser Origin Separation | C27: V3.5.4 | D27: Verify that separate applications are hosted on different hostnames to leverage the restrictions provided by same-origin policy, including how documents or scripts loaded by one origin can interact with resources from another origin and hostname-based restrictions on cookies. | E27: 2 | F27: Not Applicable | G27: GhostReport is implemented as a single Spring Boot application serving static frontend and APIs; no separate browser applications or hostnames are defined. | H27: N/A – single application in current Sprint 1 scope
A28: V3.5 | B28: Browser Origin Separation | C28: V3.5.5 | D28: Verify that messages received by the postMessage interface are discarded if the origin of the message is not trusted, or if the syntax of the message is invalid. | E28: 2 | F28: Not Applicable | G28: No postMessage usage was found in the static frontend. | H28: No postMessage usage was found in the static frontend.
A29: V3.5 | B29: Browser Origin Separation | C29: V3.5.6 | D29: Verify that JSONP functionality is not enabled anywhere across the application to avoid Cross-Site Script Inclusion (XSSI) attacks. | E29: 3 | F29: In Progress | G29: No JSONP or callback-based JSON endpoints were fully implemented. | H29: Controllers under src/main/java/com/ghostreport/controller; static frontend files
A30: V3.5 | B30: Browser Origin Separation | C30: V3.5.7 | D30: Verify that data requiring authorization is not included in script resource responses, like JavaScript files, to prevent Cross-Site Script Inclusion (XSSI) attacks. | E30: 3 | F30: Compliant | G30: JavaScript resources are static files and do not include authorization-required user data; protected data is retrieved through JSON API calls. | H30: js/api.js; admin.html; analyst.html; auditor.html; SecurityConfig.java
A31: V3.5 | B31: Browser Origin Separation | C31: V3.5.8 | D31: Verify that authenticated resources (such as images, videos, scripts, and other documents) can be loaded or embedded on behalf of the user only when intended. This can be accomplished by strict validation of the Sec-Fetch-* HTTP request header fields to ensure that the request did not originate from an inappropriate cross-origin call, or by setting a restrictive Cross-Origin-Resource-Policy HTTP response header field to instruct the browser to block returned content. | E31: 3 | F31: In Progress | G31: Frame embedding is restricted, and authenticated resources require Bearer/RBAC, but no Sec-Fetch validation or Cross-Origin-Resource-Policy header is configured. | H31: SecurityConfig.java; ReportService.java; AdminBackupController.java
A32: V3.6 | B32: External Resource Integrity
A33: V3.6 | B33: External Resource Integrity | C33: V3.6.1 | D33: Verify that client-side assets, such as JavaScript libraries, CSS, or web fonts, are only hosted externally (e.g., on a Content Delivery Network) if the resource is static and versioned and Subresource Integrity (SRI) is used to validate the integrity of the asset. If this is not possible, there should be a documented security decision to justify this for each resource. | E33: 3 | F33: Not Applicable | G33: No external client-side scripts, stylesheets, fonts, or CDN assets were found, so SRI is not applicable. | H33: static HTML files; js/api.js; css files
A34: V3.7 | B34: Other Browser Security Considerations
A35: V3.7 | B35: Other Browser Security Considerations | C35: V3.7.1 | D35: Verify that the application only uses client-side technologies which are still supported and considered secure. Examples of technologies which do not meet this requirement include NSAPI plugins, Flash, Shockwave, ActiveX, Silverlight, NACL, or client-side Java applets. | E35: 2 | F35: Compliant | G35: The frontend uses supported standard HTML, CSS, and vanilla JavaScript only; no obsolete browser plugins or unsupported client technologies were found. | H35: src/main/resources/static/*.html; src/main/resources/static/js/api.js; css files
A36: V3.7 | B36: Other Browser Security Considerations | C36: V3.7.2 | D36: Verify that the application will only automatically redirect the user to a different hostname or domain (which is not controlled by the application) where the destination appears on an allowlist. | E36: 2 | F36: Not Applicable | G36: No automatic redirects to external domains were found; the only automatic redirect is internal to track.html. | H36: N/A – frontend/browser functionality not in current system scope
A37: V3.7 | B37: Other Browser Security Considerations | C37: V3.7.3 | D37: Verify that the application shows a notification when the user is being redirected to a URL outside of the application's control, with an option to cancel the navigation. | E37: 3 | F37: Not Applicable | G37: No redirects outside the application’s control were implemented. | H37: N/A – no external redirects implemented
A38: V3.7 | B38: Other Browser Security Considerations | C38: V3.7.4 | D38: Verify that the application's top-level domain (e.g., site.tld) is added to the public preload list for HTTP Strict Transport Security (HSTS). This ensures that the use of TLS for the application is built directly into the main browsers, rather than relying only on the Strict-Transport-Security response header field. | E38: 3 | F38: Not Started | G38: HTTPS is required, but HSTS preload configuration is not defined. | H38: DESOFS Phase 1: assumptions §2.2 HTTPS; §5.3 RS7; AC9/AC10
A39: V3.7 | B39: Other Browser Security Considerations | C39: V3.7.5 | D39: Verify that the application behaves as documented (such as warning the user or blocking access) if the browser used to access the application does not support the expected security features. | E39: 3 | F39: Not Started | G39: No browser-specific behavior or fallback mechanisms are defined in the design. | H39: Project.pdf: backend API, 3 roles, OS/file ops, ASVS deliverable

Sheet V4 - API and Web Service
A1: Section ID | B1: Section Name | C1: Req ID | D1: Description | E1: Level | F1: Status | G1: Observations | H1: Reference / Link
A2: V4.1 | B2: Generic Web Service Security
A3: V4.1 | B3: Generic Web Service Security | C3: V4.1.1 | D3: Verify that every HTTP response with a message body contains a Content-Type header field that matches the actual content of the response, including the charset parameter to specify safe character encoding (e.g., UTF-8, ISO-8859-1) according to IANA Media Types, such as "text/", "/+xml" and "/xml". | E3: 1 | F3: In Progress | G3: Spring MVC and static resource handling provide content types for JSON/static HTML, and downloads set explicit media types, but content type and charset coverage is not tested for all response bodies. | H3: ReportController.java; GlobalExceptionHandler.java; ReportService.java; AdminBackupController.java; SecurityHeadersTest
A4: V4.1 | B4: Generic Web Service Security | C4: V4.1.2 | D4: Verify that only user-facing endpoints (intended for manual web-browser access) automatically redirect from HTTP to HTTPS, while other services or endpoints do not implement transparent redirects. This is to avoid a situation where a client is erroneously sending unencrypted HTTP requests, but since the requests are being automatically redirected to HTTPS, the leakage of sensitive data goes undiscovered. | E4: 2 | F4: In Progress | G4: HSTS and HTTPS/TLS are mentioned/configured, but no HTTPS redirect/rejection policy distinguishes user-facing pages from sensitive API requests. | H4: SecurityConfig.java; application.yaml; README.md
A5: V4.1 | B5: Generic Web Service Security | C5: V4.1.3 | D5: Verify that any HTTP header field used by the application and set by an intermediary layer, such as a load balancer, a web proxy, or a backend-for-frontend service, cannot be overridden by the end-user. Example headers might include X-Real-IP, X-Forwarded-*, or X-User-ID. | E5: 2 | F5: In Progress | G5: The application does not read X-Forwarded-*, X-Real-IP, or X-User-ID headers directly, but no explicit proxy/intermediary header trust policy or tests were implemented. | H5: ReportController.java; SecurityConfig.java; No ForwardedHeaderFilter or forward-headers-strategy implemented
A6: V4.1 | B6: Generic Web Service Security | C6: V4.1.4 | D6: Verify that only HTTP methods that are explicitly supported by the application or its API (including OPTIONS during preflight requests) can be used and that unused methods are blocked. | E6: 3 | F6: In Progress | G6: Controllers expose explicit GET/POST/PATCH mappings, but unsupported method blocking is not explicitly configured or tested. | H6: ReportController.java; AnalystController.java; AdminController.java; AuditController.java; AdminBackupController.java
A7: V4.1 | B7: Generic Web Service Security | C7: V4.1.5 | D7: Verify that per-message digital signatures are used to provide additional assurance on top of transport protections for requests or transactions which are highly sensitive or which traverse a number of systems. | E7: 3 | F7: Not Applicable | G7: Not applicable in the current system design. | H7: N/A – not in current system scope
A8: V4.2 | B8: HTTP Message Structure Validation
A9: V4.2 | B9: HTTP Message Structure Validation | C9: V4.2.1 | D9: Verify that all application components (including load balancers, firewalls, and application servers) determine boundaries of incoming HTTP messages using the appropriate mechanism for the HTTP version to prevent HTTP request smuggling. In HTTP/1.x, if a Transfer-Encoding header field is present, the Content-Length header must be ignored per RFC 2616. When using HTTP/2 or HTTP/3, if a Content-Length header field is present, the receiver must ensure that it is consistent with the length of the DATA frames. | E9: 2 | F9: In Progress | G9: Request boundary handling appears to rely on Spring Boot embedded server defaults; no explicit request smuggling protection, proxy configuration, or tests were found. | H9: pom.xml; application.yaml
A10: V4.2 | B10: HTTP Message Structure Validation | C10: V4.2.2 | D10: Verify that when generating HTTP messages, the Content-Length header field does not conflict with the length of the content as determined by the framing of the HTTP protocol, in order to prevent request smuggling attacks. | E10: 3 | F10: In Progress | G10: The application does not manually set Content-Length and relies on Spring/Tomcat response framing, but no tests or explicit configuration verify conflicting framing is prevented. | H10: ReportService.java; AdminBackupController.java; No manual Content-Length evidence
A11: V4.2 | B11: HTTP Message Structure Validation | C11: V4.2.3 | D11: Verify that the application does not send nor accept HTTP/2 or HTTP/3 messages with connection-specific header fields such as Transfer-Encoding to prevent response splitting and header injection attacks. | E11: 3 | F11: In Progress | G11: No manual Transfer-Encoding or connection-specific HTTP/2/HTTP/3 header handling was found, but there is no explicit HTTP/2/3 proxy/server policy or test evidence. | H11: application.yaml; pom.xml
A12: V4.2 | B12: HTTP Message Structure Validation | C12: V4.2.4 | D12: Verify that the application only accepts HTTP/2 and HTTP/3 requests where the header fields and values do not contain any CR (\r), LF (\n), or CRLF (\r\n) sequences, to prevent header injection attacks. | E12: 3 | F12: In Progress | G12: Header values are mostly constants or built with Spring ContentDisposition, but CR/LF header injection rejection is not explicitly configured or tested. | H12: SecurityConfig.java; ReportService.java; AdminBackupController.java
A13: V4.2 | B13: HTTP Message Structure Validation | C13: V4.2.5 | D13: Verify that, if the application (backend or frontend) builds and sends requests, it uses validation, sanitization, or other mechanisms to avoid creating URIs (such as for API calls) or HTTP request header fields (such as Authorization or Cookie), which are too long to be accepted by the receiving component. This could cause a denial of service, such as when sending an overly long request (e.g., a long cookie header field), which results in the server always responding with an error status. | E13: 3 | F13: In Progress | G13: Multipart size limits and file size checks exist, but URI/header length limits and Authorization header size limits are not configured or tested. | H13: application.yaml; FileStorageService.java; RateLimiterService.java
A14: V4.3 | B14: GraphQL
